Workbook

Sheet Overview
B2: PRISM-LEO Threat & Exploit Atlas: Overview
B3: Every number on this page is a live formula over Threat Atlas (rows 6-300), CVE Register and Mitigations. Edit a row there and this page updates. Checks at the bottom must read OK.
B5: Atlas entries | C5: Peer-reviewed | D5: Non-peer-reviewed | E5: CVEs in register | F5: Mitigations | G5: Real-world (E3)
B6: =COUNTA('Threat Atlas'!$A$6:$A$300) -> 78 | C6: =COUNTIF('Threat Atlas'!$R$6:$R$300,"Yes") -> 55 | D6: =COUNTIF('Threat Atlas'!$R$6:$R$300,"No") -> 23 | E6: =COUNTA('CVE Register'!$B$6:$B$300) -> 57 | F6: =COUNTA(Mitigations!$A$6:$A$300) -> 25 | G6: =COUNTIF('Threat Atlas'!$O$6:$O$300,"E3") -> 19
B8: 1. Evidence status by peer review
B9: Exploitation status | C9: Peer-reviewed | D9: Non-peer-reviewed | E9: Total | F9: Share | G9: Original set | H9: Added
B10: Demonstrated in Real-World / Active Exploit | C10: =COUNTIFS('Threat Atlas'!$J$6:$J$300,$B10,'Threat Atlas'!$R$6:$R$300,"Yes") -> 5 | D10: =COUNTIFS('Threat Atlas'!$J$6:$J$300,$B10,'Threat Atlas'!$R$6:$R$300,"No") -> 14 | E10: =C10+D10 -> 19 | F10: =IF($E$13=0,0,E10/$E$13) -> 0.24358974 | G10: =COUNTIFS('Threat Atlas'!$J$6:$J$300,$B10,'Threat Atlas'!$AK$6:$AK$300,"Original review set") -> 2 | H10: =COUNTIFS('Threat Atlas'!$J$6:$J$300,$B10,'Threat Atlas'!$AK$6:$AK$300,"Added 13 Oct 2026") -> 17
B11: Simulated / Proof-of-Concept | C11: =COUNTIFS('Threat Atlas'!$J$6:$J$300,$B11,'Threat Atlas'!$R$6:$R$300,"Yes") -> 28 | D11: =COUNTIFS('Threat Atlas'!$J$6:$J$300,$B11,'Threat Atlas'!$R$6:$R$300,"No") -> 7 | E11: =C11+D11 -> 35 | F11: =IF($E$13=0,0,E11/$E$13) -> 0.44871795 | G11: =COUNTIFS('Threat Atlas'!$J$6:$J$300,$B11,'Threat Atlas'!$AK$6:$AK$300,"Original review set") -> 20 | H11: =COUNTIFS('Threat Atlas'!$J$6:$J$300,$B11,'Threat Atlas'!$AK$6:$AK$300,"Added 13 Oct 2026") -> 15
B12: Theoretical / Unexploited | C12: =COUNTIFS('Threat Atlas'!$J$6:$J$300,$B12,'Threat Atlas'!$R$6:$R$300,"Yes") -> 22 | D12: =COUNTIFS('Threat Atlas'!$J$6:$J$300,$B12,'Threat Atlas'!$R$6:$R$300,"No") -> 2 | E12: =C12+D12 -> 24 | F12: =IF($E$13=0,0,E12/$E$13) -> 0.30769231 | G12: =COUNTIFS('Threat Atlas'!$J$6:$J$300,$B12,'Threat Atlas'!$AK$6:$AK$300,"Original review set") -> 21 | H12: =COUNTIFS('Threat Atlas'!$J$6:$J$300,$B12,'Threat Atlas'!$AK$6:$AK$300,"Added 13 Oct 2026") -> 3
B13: Total | C13: =SUM(C10:C12) -> 55 | D13: =SUM(D10:D12) -> 23 | E13: =SUM(E10:E12) -> 78 | F13: =SUM(F10:F12) -> 1 | G13: =SUM(G10:G12) -> 43 | H13: =SUM(H10:H12) -> 35
B15: 2. Entries by source type
B16: Source type | C16: Entries | D16: Real-world (E3) | E16: PoC (E1-E2) | F16: Theoretical (E0) | G16: Share
B17: Peer-reviewed journal | C17: =COUNTIF('Threat Atlas'!$Q$6:$Q$300,$B17) -> 24 | D17: =COUNTIFS('Threat Atlas'!$Q$6:$Q$300,$B17,'Threat Atlas'!$O$6:$O$300,"E3") -> 1 | E17: =COUNTIFS('Threat Atlas'!$Q$6:$Q$300,$B17,'Threat Atlas'!$O$6:$O$300,"E2")+COUNTIFS('Threat Atlas'!$Q$6:$Q$300,$B17,'Threat Atlas'!$O$6:$O$300,"E1") -> 4 | F17: =COUNTIFS('Threat Atlas'!$Q$6:$Q$300,$B17,'Threat Atlas'!$O$6:$O$300,"E0") -> 19 | G17: =IF($C$25=0,0,C17/$C$25) -> 0.30769231
B18: Peer-reviewed conference | C18: =COUNTIF('Threat Atlas'!$Q$6:$Q$300,$B18) -> 26 | D18: =COUNTIFS('Threat Atlas'!$Q$6:$Q$300,$B18,'Threat Atlas'!$O$6:$O$300,"E3") -> 3 | E18: =COUNTIFS('Threat Atlas'!$Q$6:$Q$300,$B18,'Threat Atlas'!$O$6:$O$300,"E2")+COUNTIFS('Threat Atlas'!$Q$6:$Q$300,$B18,'Threat Atlas'!$O$6:$O$300,"E1") -> 21 | F18: =COUNTIFS('Threat Atlas'!$Q$6:$Q$300,$B18,'Threat Atlas'!$O$6:$O$300,"E0") -> 2 | G18: =IF($C$25=0,0,C18/$C$25) -> 0.33333333
B19: Peer-reviewed workshop | C19: =COUNTIF('Threat Atlas'!$Q$6:$Q$300,$B19) -> 5 | D19: =COUNTIFS('Threat Atlas'!$Q$6:$Q$300,$B19,'Threat Atlas'!$O$6:$O$300,"E3") -> 1 | E19: =COUNTIFS('Threat Atlas'!$Q$6:$Q$300,$B19,'Threat Atlas'!$O$6:$O$300,"E2")+COUNTIFS('Threat Atlas'!$Q$6:$Q$300,$B19,'Threat Atlas'!$O$6:$O$300,"E1") -> 3 | F19: =COUNTIFS('Threat Atlas'!$Q$6:$Q$300,$B19,'Threat Atlas'!$O$6:$O$300,"E0") -> 1 | G19: =IF($C$25=0,0,C19/$C$25) -> 0.064102564
B20: Preprint / unconfirmed venue | C20: =COUNTIF('Threat Atlas'!$Q$6:$Q$300,$B20) -> 3 | D20: =COUNTIFS('Threat Atlas'!$Q$6:$Q$300,$B20,'Threat Atlas'!$O$6:$O$300,"E3") -> 1 | E20: =COUNTIFS('Threat Atlas'!$Q$6:$Q$300,$B20,'Threat Atlas'!$O$6:$O$300,"E2")+COUNTIFS('Threat Atlas'!$Q$6:$Q$300,$B20,'Threat Atlas'!$O$6:$O$300,"E1") -> 1 | F20: =COUNTIFS('Threat Atlas'!$Q$6:$Q$300,$B20,'Threat Atlas'!$O$6:$O$300,"E0") -> 1 | G20: =IF($C$25=0,0,C20/$C$25) -> 0.038461538
B21: Conference talk / event (non-peer-reviewed) | C21: =COUNTIF('Threat Atlas'!$Q$6:$Q$300,$B21) -> 9 | D21: =COUNTIFS('Threat Atlas'!$Q$6:$Q$300,$B21,'Threat Atlas'!$O$6:$O$300,"E3") -> 3 | E21: =COUNTIFS('Threat Atlas'!$Q$6:$Q$300,$B21,'Threat Atlas'!$O$6:$O$300,"E2")+COUNTIFS('Threat Atlas'!$Q$6:$Q$300,$B21,'Threat Atlas'!$O$6:$O$300,"E1") -> 6 | F21: =COUNTIFS('Threat Atlas'!$Q$6:$Q$300,$B21,'Threat Atlas'!$O$6:$O$300,"E0") -> 0 | G21: =IF($C$25=0,0,C21/$C$25) -> 0.11538462
B22: Government / regulator advisory | C22: =COUNTIF('Threat Atlas'!$Q$6:$Q$300,$B22) -> 3 | D22: =COUNTIFS('Threat Atlas'!$Q$6:$Q$300,$B22,'Threat Atlas'!$O$6:$O$300,"E3") -> 2 | E22: =COUNTIFS('Threat Atlas'!$Q$6:$Q$300,$B22,'Threat Atlas'!$O$6:$O$300,"E2")+COUNTIFS('Threat Atlas'!$Q$6:$Q$300,$B22,'Threat Atlas'!$O$6:$O$300,"E1") -> 0 | F22: =COUNTIFS('Threat Atlas'!$Q$6:$Q$300,$B22,'Threat Atlas'!$O$6:$O$300,"E0") -> 1 | G22: =IF($C$25=0,0,C22/$C$25) -> 0.038461538
B23: Documented incident report | C23: =COUNTIF('Threat Atlas'!$Q$6:$Q$300,$B23) -> 5 | D23: =COUNTIFS('Threat Atlas'!$Q$6:$Q$300,$B23,'Threat Atlas'!$O$6:$O$300,"E3") -> 5 | E23: =COUNTIFS('Threat Atlas'!$Q$6:$Q$300,$B23,'Threat Atlas'!$O$6:$O$300,"E2")+COUNTIFS('Threat Atlas'!$Q$6:$Q$300,$B23,'Threat Atlas'!$O$6:$O$300,"E1") -> 0 | F23: =COUNTIFS('Threat Atlas'!$Q$6:$Q$300,$B23,'Threat Atlas'!$O$6:$O$300,"E0") -> 0 | G23: =IF($C$25=0,0,C23/$C$25) -> 0.064102564
B24: Industry / NGO report | C24: =COUNTIF('Threat Atlas'!$Q$6:$Q$300,$B24) -> 3 | D24: =COUNTIFS('Threat Atlas'!$Q$6:$Q$300,$B24,'Threat Atlas'!$O$6:$O$300,"E3") -> 3 | E24: =COUNTIFS('Threat Atlas'!$Q$6:$Q$300,$B24,'Threat Atlas'!$O$6:$O$300,"E2")+COUNTIFS('Threat Atlas'!$Q$6:$Q$300,$B24,'Threat Atlas'!$O$6:$O$300,"E1") -> 0 | F24: =COUNTIFS('Threat Atlas'!$Q$6:$Q$300,$B24,'Threat Atlas'!$O$6:$O$300,"E0") -> 0 | G24: =IF($C$25=0,0,C24/$C$25) -> 0.038461538
B25: Total | C25: =SUM(C17:C24) -> 78 | D25: =SUM(D17:D24) -> 19 | E25: =SUM(E17:E24) -> 35 | F25: =SUM(F17:F24) -> 24 | G25: =SUM(G17:G24) -> 1
B27: 3. Entries, evidence, CVEs and mitigations by PRISM-LEO layer
B28: Layer | C28: Entry layer | D28: Impact layer | E28: Impact, E2-E3 | F28: Impact, E3 only | G28: CVEs (component) | H28: Mitigations (primary)
B29: L1 Physical & Infrastructure | C29: =COUNTIF('Threat Atlas'!$Z$6:$Z$300,"L1") -> 49 | D29: =COUNTIF('Threat Atlas'!$AA$6:$AA$300,"L1") -> 20 | E29: =COUNTIFS('Threat Atlas'!$AA$6:$AA$300,"L1",'Threat Atlas'!$O$6:$O$300,"E2")+COUNTIFS('Threat Atlas'!$AA$6:$AA$300,"L1",'Threat Atlas'!$O$6:$O$300,"E3") -> 11 | F29: =COUNTIFS('Threat Atlas'!$AA$6:$AA$300,"L1",'Threat Atlas'!$O$6:$O$300,"E3") -> 3 | G29: =COUNTIF('CVE Register'!$M$6:$M$300,"L1") -> 9 | H29: =COUNTIF(Mitigations!$G$6:$G$300,"L1") -> 7
B30: L2 Data & Communication | C30: =COUNTIF('Threat Atlas'!$Z$6:$Z$300,"L2") -> 23 | D30: =COUNTIF('Threat Atlas'!$AA$6:$AA$300,"L2") -> 23 | E30: =COUNTIFS('Threat Atlas'!$AA$6:$AA$300,"L2",'Threat Atlas'!$O$6:$O$300,"E2")+COUNTIFS('Threat Atlas'!$AA$6:$AA$300,"L2",'Threat Atlas'!$O$6:$O$300,"E3") -> 6 | F30: =COUNTIFS('Threat Atlas'!$AA$6:$AA$300,"L2",'Threat Atlas'!$O$6:$O$300,"E3") -> 5 | G30: =COUNTIF('CVE Register'!$M$6:$M$300,"L2") -> 10 | H30: =COUNTIF(Mitigations!$G$6:$G$300,"L2") -> 3
B31: L3 Service & Processing | C31: =COUNTIF('Threat Atlas'!$Z$6:$Z$300,"L3") -> 0 | D31: =COUNTIF('Threat Atlas'!$AA$6:$AA$300,"L3") -> 19 | E31: =COUNTIFS('Threat Atlas'!$AA$6:$AA$300,"L3",'Threat Atlas'!$O$6:$O$300,"E2")+COUNTIFS('Threat Atlas'!$AA$6:$AA$300,"L3",'Threat Atlas'!$O$6:$O$300,"E3") -> 6 | F31: =COUNTIFS('Threat Atlas'!$AA$6:$AA$300,"L3",'Threat Atlas'!$O$6:$O$300,"E3") -> 3 | G31: =COUNTIF('CVE Register'!$M$6:$M$300,"L3") -> 0 | H31: =COUNTIF(Mitigations!$G$6:$G$300,"L3") -> 4
B32: L4 Governance & Integration | C32: =COUNTIF('Threat Atlas'!$Z$6:$Z$300,"L4") -> 6 | D32: =COUNTIF('Threat Atlas'!$AA$6:$AA$300,"L4") -> 16 | E32: =COUNTIFS('Threat Atlas'!$AA$6:$AA$300,"L4",'Threat Atlas'!$O$6:$O$300,"E2")+COUNTIFS('Threat Atlas'!$AA$6:$AA$300,"L4",'Threat Atlas'!$O$6:$O$300,"E3") -> 9 | F32: =COUNTIFS('Threat Atlas'!$AA$6:$AA$300,"L4",'Threat Atlas'!$O$6:$O$300,"E3") -> 8 | G32: =COUNTIF('CVE Register'!$M$6:$M$300,"L4") -> 38 | H32: =COUNTIF(Mitigations!$G$6:$G$300,"L4") -> 11
B33: Total | C33: =SUM(C29:C32) -> 78 | D33: =SUM(D29:D32) -> 78 | E33: =SUM(E29:E32) -> 32 | F33: =SUM(F29:F32) -> 19 | G33: =SUM(G29:G32) -> 57 | H33: =SUM(H29:H32) -> 25
B35: 4. Trust-boundary crossings
B36: Trust boundary | C36: Atlas entries crossing | D36: of which E2-E3 | E36: of which E3 | F36: CVEs exposed at TB | G36: Mitigations covering
B37: TB1 L1 | L2 | C37: =COUNTIF('Threat Atlas'!$AC$6:$AC$300,"✓") -> 41 | D37: =COUNTIFS('Threat Atlas'!$AC$6:$AC$300,"✓",'Threat Atlas'!$O$6:$O$300,"E2")+COUNTIFS('Threat Atlas'!$AC$6:$AC$300,"✓",'Threat Atlas'!$O$6:$O$300,"E3") -> 18 | E37: =COUNTIFS('Threat Atlas'!$AC$6:$AC$300,"✓",'Threat Atlas'!$O$6:$O$300,"E3") -> 13 | F37: =COUNTIF('CVE Register'!$N$6:$N$300,"TB1") -> 19 | G37: =COUNTIF(Mitigations!$H$6:$H$300,"*TB1*") -> 14
B38: TB2 L2 | L3 | C38: =COUNTIF('Threat Atlas'!$AD$6:$AD$300,"✓") -> 39 | D38: =COUNTIFS('Threat Atlas'!$AD$6:$AD$300,"✓",'Threat Atlas'!$O$6:$O$300,"E2")+COUNTIFS('Threat Atlas'!$AD$6:$AD$300,"✓",'Threat Atlas'!$O$6:$O$300,"E3") -> 18 | E38: =COUNTIFS('Threat Atlas'!$AD$6:$AD$300,"✓",'Threat Atlas'!$O$6:$O$300,"E3") -> 13 | F38: =COUNTIF('CVE Register'!$N$6:$N$300,"TB2") -> 0 | G38: =COUNTIF(Mitigations!$H$6:$H$300,"*TB2*") -> 8
B39: TB3 L3 | L4 | C39: =COUNTIF('Threat Atlas'!$AE$6:$AE$300,"✓") -> 20 | D39: =COUNTIFS('Threat Atlas'!$AE$6:$AE$300,"✓",'Threat Atlas'!$O$6:$O$300,"E2")+COUNTIFS('Threat Atlas'!$AE$6:$AE$300,"✓",'Threat Atlas'!$O$6:$O$300,"E3") -> 12 | E39: =COUNTIFS('Threat Atlas'!$AE$6:$AE$300,"✓",'Threat Atlas'!$O$6:$O$300,"E3") -> 10 | F39: =COUNTIF('CVE Register'!$N$6:$N$300,"TB3") -> 38 | G39: =COUNTIF(Mitigations!$H$6:$H$300,"*TB3*") -> 13
B40: Entries crossing no boundary (within layer) | C40: =COUNTIF('Threat Atlas'!$AB$6:$AB$300,"Within layer") -> 25
B42: 5. Timing dependency and propagation direction
B43: Timing dependency | C43: Entries | D43: E2-E3 | F43: Direction | G43: Entries
B44: Direct | C44: =COUNTIF('Threat Atlas'!$AF$6:$AF$300,B44) -> 26 | D44: =COUNTIFS('Threat Atlas'!$AF$6:$AF$300,B44,'Threat Atlas'!$O$6:$O$300,"E2")+COUNTIFS('Threat Atlas'!$AF$6:$AF$300,B44,'Threat Atlas'!$O$6:$O$300,"E3") -> 17 | F44: Upward (observables) | G44: =COUNTIF('Threat Atlas'!$AB$6:$AB$300,F44) -> 46
B45: Indirect | C45: =COUNTIF('Threat Atlas'!$AF$6:$AF$300,B45) -> 3 | D45: =COUNTIFS('Threat Atlas'!$AF$6:$AF$300,B45,'Threat Atlas'!$O$6:$O$300,"E2")+COUNTIFS('Threat Atlas'!$AF$6:$AF$300,B45,'Threat Atlas'!$O$6:$O$300,"E3") -> 1 | F45: Downward (config / keys / sync) | G45: =COUNTIF('Threat Atlas'!$AB$6:$AB$300,F45) -> 7
B46: None | C46: =COUNTIF('Threat Atlas'!$AF$6:$AF$300,B46) -> 49 | D46: =COUNTIFS('Threat Atlas'!$AF$6:$AF$300,B46,'Threat Atlas'!$O$6:$O$300,"E2")+COUNTIFS('Threat Atlas'!$AF$6:$AF$300,B46,'Threat Atlas'!$O$6:$O$300,"E3") -> 14 | F46: Within layer | G46: =COUNTIF('Threat Atlas'!$AB$6:$AB$300,F46) -> 25
B47: Total | C47: =SUM(C44:C46) -> 78 | D47: =SUM(D44:D46) -> 32 | F47: Total | G47: =SUM(G44:G46) -> 78
...

Sheet Threat Atlas
A1: PRISM-LEO Threat & Exploit Atlas
A2: Vulnerabilities vs. demonstrated exploits for GNSS-independent LEO MLAT-B air traffic surveillance · Rows 6-48: original peer-reviewed review set (unchanged) · Rows 49+: newer peer-reviewed and non-peer-reviewed sources · Defensive research dataset: attack descriptions are one high-level line, no operational parameters
B3: ● Demonstrated in Real-World / Active Exploit | D3: ● Simulated / Proof-of-Concept | F3: ● Theoretical / Unexploited | H3: Rankings checked 4 Oct 2026 (ICORE2026 / SJR 2025); new venues 13 Oct 2026. Every source link (col T) and every CVE (CVE Register) checked 13 Oct 2026. Columns Q onward are the Atlas extension; R, S, AA-AD and AG are live formulas.
A4: ORIGINAL REVIEW COLUMNS (A-P, unchanged) | Q4: ATLAS EXTENSION (13 Oct 2026) | Y4: ▼ ASSET (added 16 Oct 2026) | AL4: ▼ SATERA ASSETS & CROSS-LAYER PROPAGATION (added 29 Oct 2026)
A5: # | B5: Paper Title | C5: Authors & Year | D5: Publication Venue | E5: Venue Ranking / Quartile | F5: Ranking Source (checked 4 Oct 2026) | G5: Threat Category | H5: Vulnerability Category | I5: Attack Category | J5: Exploitation Feasibility / Status | K5: Evidence Basis | L5: Key Findings & Empirical Evidence | M5: BibTeX Key | N5: Domain | O5: Evidence Level (E0–E3) | P5: Placement in TDSC Draft | Q5: Source Type | R5: Peer-reviewed | S5: Citation | T5: Verified Link | U5: Link Check (13 Oct 2026) | V5: Vulnerability Class | W5: Attack Category (normalised) | X5: Attack (one line, high level) | Y5: Asset | Z5: Entry Layer | AA5: Impact Layer | AB5: Direction (derived) | AC5: TB1 | AD5: TB2 | AE5: TB3 | AF5: Timing Dependency | AG5: Related CVEs | AH5: CVEs in Register | AI5: Mitigation IDs | AJ5: Propagation / Notes | AK5: Atlas Set | AL5: Asset ID(s) (SATERA register) | AM5: Asset basis | AN5: Cross-layer propagation (layers and assets the effect can reach)
A6: 1 | B6: Undermining Privacy in the Aircraft Communications Addressing and Reporting System (ACARS) | C6: Smith et al. (2018) | D6: Proceedings on Privacy Enhancing Technologies (PoPETs) | E6: ICORE2026 A | F6: ICORE: PETS | G6: Passive eavesdropper with low-cost SDR; privacy / intelligence motive | H6: Design gap: plaintext data link; weak proprietary cipher | I6: Eavesdropping; cryptanalysis; traffic analysis | J6: Demonstrated in Real-World / Active Exploit | K6: Passive interception of live operational traffic | L6: Collected live ACARS traffic and broke the weak cipher some operators use, exposing sensitive data on military, government and business flights. | M6: Smith2018ACARSPrivacy | N6: Aviation data links | O6: E3 | P6: Table 2, [46] | Q6: Peer-reviewed conference | R6: =IF(LEFT(Q6,13)="Peer-reviewed","Yes","No") -> Yes | S6: =C6&". "&CHAR(34)&B6&CHAR(34)&". "&D6&"." -> Smith et al. (2018). "Undermining Privacy in the Aircraft Communications Addressing and Reporting System (ACARS)". Proceedings on Privacy Enhancing Technologies (PoPETs). | T6: https://doi.org/10.1515/popets-2018-0023 | U6: DOI metadata checked 13 Oct 2026 (OpenAlex): title matches | V6: Protocol design gap | W6: Eavesdropping / traffic analysis | X6: Passive SDR reception of ACARS traffic and recovery of weakly enciphered messages. | Y6: L2 · Aeronautical data links (ACARS, CPDLC, ADS-C, LDACS) | Z6: L2 | AA6: L2 | AB6: =IF(OR(Z6="",AA6=""),"",IF(VALUE(MID(AA6,2,1))>VALUE(MID(Z6,2,1)),"Upward (observables)",IF(VALUE(MID(AA6,2,1))<VALUE(MID(Z6,2,1)),"Downward (config / keys / sync)","Within layer"))) -> Within layer | AC6: =IF(OR(Z6="",AA6=""),"",IF(AND(MIN(VALUE(MID(Z6,2,1)),VALUE(MID(AA6,2,1)))<=1,MAX(VALUE(MID(Z6,2,1)),VALUE(MID(AA6,2,1)))>=2),"✓","")) | AD6: =IF(OR(Z6="",AA6=""),"",IF(AND(MIN(VALUE(MID(Z6,2,1)),VALUE(MID(AA6,2,1)))<=2,MAX(VALUE(MID(Z6,2,1)),VALUE(MID(AA6,2,1)))>=3),"✓","")) | AE6: =IF(OR(Z6="",AA6=""),"",IF(AND(MIN(VALUE(MID(Z6,2,1)),VALUE(MID(AA6,2,1)))<=3,MAX(VALUE(MID(Z6,2,1)),VALUE(MID(AA6,2,1)))>=4),"✓","")) | AF6: None | AH6: =COUNTIF('CVE Register'!$P$6:$P$300,A6) -> 0 | AI6: M22 | AJ6: Confidentiality only; no integrity effect on surveillance. | AK6: Original review set | AL6: A4.3 | AM6: Bound threats: T4.04 | AN6: Contained: disclosure only, no downstream state change. Exposure at L4: [A4.3]
A7: 2 | B7: A Tale of Sea and Sky: On the Security of Maritime VSAT Communications | C7: Pavur et al. (2020) | D7: IEEE Symposium on Security and Privacy (S&P) | E7: ICORE2026 A* | F7: ICORE: SP | G7: Passive eavesdropper with consumer satellite-TV equipment | H7: Architectural weakness: unencrypted VSAT links; insecure default configurations | I7: Eavesdropping; TCP session hijacking | J7: Demonstrated in Real-World / Active Exploit | K7: Passive interception of live third-party traffic; TCP hijack executed only on the authors' own connection over the live network | L7: Intercepted live maritime VSAT traffic across a wide footprint with under $400 of equipment and recovered sensitive data; demonstrated TCP session hijacking against their own connection without touching vessel traffic. | M7: Pavur2020VSAT | N7: Satellite & space | O7: E3 | P7: Table 2, [50] | Q7: Peer-reviewed conference | R7: =IF(LEFT(Q7,13)="Peer-reviewed","Yes","No") -> Yes | S7: =C7&". "&CHAR(34)&B7&CHAR(34)&". "&D7&"." -> Pavur et al. (2020). "A Tale of Sea and Sky: On the Security of Maritime VSAT Communications". IEEE Symposium on Security and Privacy (S&P). | T7: https://doi.org/10.1109/SP40000.2020.00056 | U7: DOI metadata checked 13 Oct 2026 (OpenAlex): title matches | V7: Protocol design gap | W7: Eavesdropping / traffic analysis | X7: Passive interception of unencrypted maritime VSAT traffic; session hijack shown only on the authors' own link. | Y7: L2 · SATCOM broadband links | Z7: L2 | AA7: L2 | AB7: =IF(OR(Z7="",AA7=""),"",IF(VALUE(MID(AA7,2,1))>VALUE(MID(Z7,2,1)),"Upward (observables)",IF(VALUE(MID(AA7,2,1))<VALUE(MID(Z7,2,1)),"Downward (config / keys / sync)","Within layer"))) -> Within layer | AC7: =IF(OR(Z7="",AA7=""),"",IF(AND(MIN(VALUE(MID(Z7,2,1)),VALUE(MID(AA7,2,1)))<=1,MAX(VALUE(MID(Z7,2,1)),VALUE(MID(AA7,2,1)))>=2),"✓","")) | AD7: =IF(OR(Z7="",AA7=""),"",IF(AND(MIN(VALUE(MID(Z7,2,1)),VALUE(MID(AA7,2,1)))<=2,MAX(VALUE(MID(Z7,2,1)),VALUE(MID(AA7,2,1)))>=3),"✓","")) | AE7: =IF(OR(Z7="",AA7=""),"",IF(AND(MIN(VALUE(MID(Z7,2,1)),VALUE(MID(AA7,2,1)))<=3,MAX(VALUE(MID(Z7,2,1)),VALUE(MID(AA7,2,1)))>=4),"✓","")) | AF7: None | AH7: =COUNTIF('CVE Register'!$P$6:$P$300,A7) -> 0 | AI7: M13 | AJ7: Same eavesdropping class as space-to-ground downlinks. | AK7: Original review set | AL7: A2.4 | AM7: Bound threats: T2.08 | AN7: Contained: disclosure only, no downstream state change. Exposure at L2: [A2.4]
A8: 3 | B8: Experimental Analysis of Attacks on Next Generation Air Traffic Communication | C8: Schäfer, Lenders & Martinovic (2013) | D8: Applied Cryptography and Network Security (ACNS) | E8: ICORE2026 B | F8: ICORE: ACNS | G8: Low-budget attacker with COTS SDR; no insider access | H8: Inherent protocol flaw: unauthenticated, unencrypted ADS-B broadcast | I8: Ghost injection; flooding; jamming; message deletion / modification; eavesdropping | J8: Simulated / Proof-of-Concept | K8: Real hardware, controlled setting | L8: Showed inexpensive SDR equipment can execute the main ADS-B attacks against real receivers, establishing practical feasibility outside operational ATC. | M8: Schafer2013ExperimentalADSB | N8: Aviation surveillance (ADS-B / MLAT) | O8: E2 | P8: Table 1, [4] | Q8: Peer-reviewed conference | R8: =IF(LEFT(Q8,13)="Peer-reviewed","Yes","No") -> Yes | S8: =C8&". "&CHAR(34)&B8&CHAR(34)&". "&D8&"." -> Schäfer, Lenders & Martinovic (2013). "Experimental Analysis of Attacks on Next Generation Air Traffic Communication". Applied Cryptography and Network Security (ACNS). | T8: https://doi.org/10.1007/978-3-642-38980-1_16 | U8: DOI metadata checked 13 Oct 2026 (OpenAlex): title matches | V8: Protocol design gap | W8: Spoofing / injection | X8: Injection of forged ADS-B messages and jamming against real receivers with COTS SDR. | Y8: L1 · Transponder signals & satellite receivers (ADS-B / Mode S) | Z8: L1 | AA8: L2 | AB8: =IF(OR(Z8="",AA8=""),"",IF(VALUE(MID(AA8,2,1))>VALUE(MID(Z8,2,1)),"Upward (observables)",IF(VALUE(MID(AA8,2,1))<VALUE(MID(Z8,2,1)),"Downward (config / keys / sync)","Within layer"))) -> Upward (observables) | AC8: =IF(OR(Z8="",AA8=""),"",IF(AND(MIN(VALUE(MID(Z8,2,1)),VALUE(MID(AA8,2,1)))<=1,MAX(VALUE(MID(Z8,2,1)),VALUE(MID(AA8,2,1)))>=2),"✓","")) -> ✓ | AD8: =IF(OR(Z8="",AA8=""),"",IF(AND(MIN(VALUE(MID(Z8,2,1)),VALUE(MID(AA8,2,1)))<=2,MAX(VALUE(MID(Z8,2,1)),VALUE(MID(AA8,2,1)))>=3),"✓","")) | AE8: =IF(OR(Z8="",AA8=""),"",IF(AND(MIN(VALUE(MID(Z8,2,1)),VALUE(MID(AA8,2,1)))<=3,MAX(VALUE(MID(Z8,2,1)),VALUE(MID(AA8,2,1)))>=4),"✓","")) | AF8: None | AH8: =COUNTIF('CVE Register'!$P$6:$P$300,A8) -> 0 | AI8: M15; M17; M21 | AJ8: Would reach L3 association if not filtered. | AK8: Original review set | AL8: A1.1, A1.3 | AM8: Bound threats: T1.01, T1.02, T1.04, T1.07 | AN8: L1 > L2 > L3 > L4 (4 of 4 layers) L1: [A1.1], [A1.3], A1.4, A1.7 | L2: A2.1, A2.2, A2.4 | L3: A3.1, A3.3, A3.4, A3.5, A3.6 | L4: A4.5, A4.6 Boundaries to first check A3.4/A3.5: 2 | to ATM A4.6: 3
A9: 4 | B9: Assessing the Spoofing Threat: Development of a Portable GPS Civilian Spoofer | C9: Humphreys et al. (2008) | D9: ION GNSS | E9: Not ICORE-ranked | F9: Not in ICORE2026 list | G9: Moderately resourced attacker building a receiver-spoofer | H9: Design gap: unauthenticated civil GPS signals | I9: GNSS spoofing (signal takeover / carry-off) | J9: Simulated / Proof-of-Concept | K9: Test receiver | L9: Built a portable spoofer that tracks live signals and smoothly captures a target receiver; simple consistency checks fail to detect it. | M9: Humphreys2008GPSSpoofer | N9: GNSS | O9: E2 | P9: Table 1, [29] | Q9: Peer-reviewed conference | R9: =IF(LEFT(Q9,13)="Peer-reviewed","Yes","No") -> Yes | S9: =C9&". "&CHAR(34)&B9&CHAR(34)&". "&D9&"." -> Humphreys et al. (2008). "Assessing the Spoofing Threat: Development of a Portable GPS Civilian Spoofer". ION GNSS. | T9: https://www.ion.org/publications/abstract.cfm?articleID=8132 | U9: Page fetched 13 Oct 2026: title matches | V9: Protocol design gap | W9: Spoofing / injection | X9: Receiver-spoofer that captures a civil GPS receiver's position and time solution. | Y9: L1 · GNSS receiver / onboard clock | Z9: L1 | AA9: L1 | AB9: =IF(OR(Z9="",AA9=""),"",IF(VALUE(MID(AA9,2,1))>VALUE(MID(Z9,2,1)),"Upward (observables)",IF(VALUE(MID(AA9,2,1))<VALUE(MID(Z9,2,1)),"Downward (config / keys / sync)","Within layer"))) -> Within layer | AC9: =IF(OR(Z9="",AA9=""),"",IF(AND(MIN(VALUE(MID(Z9,2,1)),VALUE(MID(AA9,2,1)))<=1,MAX(VALUE(MID(Z9,2,1)),VALUE(MID(AA9,2,1)))>=2),"✓","")) | AD9: =IF(OR(Z9="",AA9=""),"",IF(AND(MIN(VALUE(MID(Z9,2,1)),VALUE(MID(AA9,2,1)))<=2,MAX(VALUE(MID(Z9,2,1)),VALUE(MID(AA9,2,1)))>=3),"✓","")) | AE9: =IF(OR(Z9="",AA9=""),"",IF(AND(MIN(VALUE(MID(Z9,2,1)),VALUE(MID(AA9,2,1)))<=3,MAX(VALUE(MID(Z9,2,1)),VALUE(MID(AA9,2,1)))>=4),"✓","")) | AF9: Direct | AH9: =COUNTIF('CVE Register'!$P$6:$P$300,A9) -> 0 | AI9: M01; M12; M18; M19; M23 | AJ9: Threatens any GNSS-disciplined clock in the sync chain. | AK9: Original review set | AL9: A1.2, A1.5 | AM9: Bound threats: T1.11 | AN9: L1 > L2 > L3 > L4 (4 of 4 layers) L1: [A1.2], [A1.5], A1.4, A1.7 | L2: A2.1, A2.2, A2.4 | L3: A3.1, A3.2, A3.3, A3.4, A3.5, A3.6 | L4: A4.5, A4.6 Boundaries to first check A3.4/A3.5: 2 | to ATM A4.6: 3
A10: 5 | B10: Investigation of Multi-device Location Spoofing Attacks on Air Traffic Control and Possible Countermeasures | C10: Moser et al. (2016) | D10: ACM MobiCom | E10: ICORE2026 A* | F10: ICORE: MOBICOM | G10: Strong attacker with multiple time-synchronised transmitters | H10: Architectural weakness: MLAT / TDOA verification assumes a single emitter | I10: Multi-device location spoofing defeating multilateration | J10: Simulated / Proof-of-Concept | K10: Real COTS SDR hardware; attack launched against the live OpenSky Network (crowdsourced, non-ATC) | L10: Built a multi-device attack from COTS SDRs and launched it against the OpenSky Network: timing errors of distributed spoofed signals were indistinguishable from a genuine single emitter. Frequency offset and transient phase noise detect multi-source spoofing. | M10: Moser2016MultiDevice | N10: Aviation surveillance (ADS-B / MLAT) | O10: E2 | P10: Table 1, [9] | Q10: Peer-reviewed conference | R10: =IF(LEFT(Q10,13)="Peer-reviewed","Yes","No") -> Yes | S10: =C10&". "&CHAR(34)&B10&CHAR(34)&". "&D10&"." -> Moser et al. (2016). "Investigation of Multi-device Location Spoofing Attacks on Air Traffic Control and Possible Countermeasures". ACM MobiCom. | T10: https://doi.org/10.1145/2973750.2973763 | U10: DOI metadata checked 13 Oct 2026 (OpenAlex): title matches | V10: Architectural weakness | W10: Spoofing / injection | X10: Time-synchronised multi-transmitter spoofing that looks consistent to multilateration. | Y10: L1 · Transponder signals & satellite receivers (ADS-B / Mode S) | Z10: L1 | AA10: L3 | AB10: =IF(OR(Z10="",AA10=""),"",IF(VALUE(MID(AA10,2,1))>VALUE(MID(Z10,2,1)),"Upward (observables)",IF(VALUE(MID(AA10,2,1))<VALUE(MID(Z10,2,1)),"Downward (config / keys / sync)","Within layer"))) -> Upward (observables) | AC10: =IF(OR(Z10="",AA10=""),"",IF(AND(MIN(VALUE(MID(Z10,2,1)),VALUE(MID(AA10,2,1)))<=1,MAX(VALUE(MID(Z10,2,1)),VALUE(MID(AA10,2,1)))>=2),"✓","")) -> ✓ | AD10: =IF(OR(Z10="",AA10=""),"",IF(AND(MIN(VALUE(MID(Z10,2,1)),VALUE(MID(AA10,2,1)))<=2,MAX(VALUE(MID(Z10,2,1)),VALUE(MID(AA10,2,1)))>=3),"✓","")) -> ✓ | AE10: =IF(OR(Z10="",AA10=""),"",IF(AND(MIN(VALUE(MID(Z10,2,1)),VALUE(MID(AA10,2,1)))<=3,MAX(VALUE(MID(Z10,2,1)),VALUE(MID(AA10,2,1)))>=4),"✓","")) | AF10: Direct | AH10: =COUNTIF('CVE Register'!$P$6:$P$300,A10) -> 0 | AI10: M15; M16; M17 | AJ10: Directly relevant to MLAT-B: defeats TDOA consistency checks. | AK10: Original review set | AL10: A1.1, A3.3, A3.5 | AM10: Bound threats: T1.05, T1.06, T3.07, T3.08 | AN10: L1 > L2 > L3 > L4 (4 of 4 layers) L1: [A1.1], A1.3, A1.4, A1.7 | L2: A2.1, A2.2, A2.4 | L3: [A3.3], [A3.5], A3.1, A3.4, A3.6 | L4: A4.5, A4.6 Boundaries to first check A3.4/A3.5: 0 (an origin is a check) | to ATM A4.6: 1
A11: 6 | B11: Secure Track Verification | C11: Schäfer, Lenders & Schmitt (2015) | D11: IEEE Symposium on Security and Privacy (S&P) | E11: ICORE2026 A* | F11: ICORE: SP | G11: ADS-B injector including multi-device attackers | H11: Protocol flaw: self-reported positions unauthenticated | I11: Location spoofing; ghost-track injection | J11: Simulated / Proof-of-Concept | K11: Attacks modelled on real sensor data | L11: Verifying a track over time with few TDOA receivers detects spoofing that single-snapshot MLAT misses; evaluated on real OpenSky data. | M11: Schafer2015SecureTrack | N11: Aviation surveillance (ADS-B / MLAT) | O11: E1 | P11: Table 1, [36] | Q11: Peer-reviewed conference | R11: =IF(LEFT(Q11,13)="Peer-reviewed","Yes","No") -> Yes | S11: =C11&". "&CHAR(34)&B11&CHAR(34)&". "&D11&"." -> Schäfer, Lenders & Schmitt (2015). "Secure Track Verification". IEEE Symposium on Security and Privacy (S&P). | T11: https://doi.org/10.1109/SP.2015.20 | U11: DOI metadata checked 13 Oct 2026 (OpenAlex): title matches | V11: Protocol design gap | W11: Spoofing / injection | X11: Location spoofing that evades single-snapshot MLAT checks; countered by track-level TDOA verification. | Y11: L1 · Transponder signals & satellite receivers (ADS-B / Mode S) | Z11: L1 | AA11: L3 | AB11: =IF(OR(Z11="",AA11=""),"",IF(VALUE(MID(AA11,2,1))>VALUE(MID(Z11,2,1)),"Upward (observables)",IF(VALUE(MID(AA11,2,1))<VALUE(MID(Z11,2,1)),"Downward (config / keys / sync)","Within layer"))) -> Upward (observables) | AC11: =IF(OR(Z11="",AA11=""),"",IF(AND(MIN(VALUE(MID(Z11,2,1)),VALUE(MID(AA11,2,1)))<=1,MAX(VALUE(MID(Z11,2,1)),VALUE(MID(AA11,2,1)))>=2),"✓","")) -> ✓ | AD11: =IF(OR(Z11="",AA11=""),"",IF(AND(MIN(VALUE(MID(Z11,2,1)),VALUE(MID(AA11,2,1)))<=2,MAX(VALUE(MID(Z11,2,1)),VALUE(MID(AA11,2,1)))>=3),"✓","")) -> ✓ | AE11: =IF(OR(Z11="",AA11=""),"",IF(AND(MIN(VALUE(MID(Z11,2,1)),VALUE(MID(AA11,2,1)))<=3,MAX(VALUE(MID(Z11,2,1)),VALUE(MID(AA11,2,1)))>=4),"✓","")) | AF11: Direct | AH11: =COUNTIF('CVE Register'!$P$6:$P$300,A11) -> 0 | AI11: M15 | AK11: Original review set | AL11: A1.1, A1.4, A3.3, A3.5 | AM11: Bound threats: T1.03, T1.05, T1.09, T3.07, T3.08 | AN11: L1 > L2 > L3 > L4 (4 of 4 layers) L1: [A1.1], [A1.4], A1.3, A1.7 | L2: A2.1, A2.2, A2.4 | L3: [A3.3], [A3.5], A3.1, A3.4, A3.6 | L4: A4.5, A4.6 Boundaries to first check A3.4/A3.5: 0 (an origin is a check) | to ATM A4.6: 1
A12: 7 | B12: Intrusion Detection for Airborne Communication Using PHY-Layer Information | C12: Strohmeier, Lenders & Martinovic (2015) | D12: DIMVA (LNCS) | E12: ICORE2026 B | F12: ICORE: DIMVA | G12: Ground-based SDR injector | H12: Protocol flaw: unauthenticated broadcast | I12: Message injection | J12: Simulated / Proof-of-Concept | K12: Emulated attacks on real data | L12: Physical-layer features such as signal strength separate injected messages from genuine aircraft with high detection rates. | M12: Strohmeier2015PHYIDS | N12: Aviation surveillance (ADS-B / MLAT) | O12: E1 | P12: Table 1, [35] | Q12: Peer-reviewed conference | R12: =IF(LEFT(Q12,13)="Peer-reviewed","Yes","No") -> Yes | S12: =C12&". "&CHAR(34)&B12&CHAR(34)&". "&D12&"." -> Strohmeier, Lenders & Martinovic (2015). "Intrusion Detection for Airborne Communication Using PHY-Layer Information". DIMVA (LNCS). | T12: https://doi.org/10.1007/978-3-319-20550-2_4 | U12: DOI metadata checked 13 Oct 2026 (OpenAlex): title matches | V12: Protocol design gap | W12: Spoofing / injection | X12: Ground-based injection of ADS-B messages, flagged using physical-layer features. | Y12: L1 · Transponder signals & satellite receivers (ADS-B / Mode S) | Z12: L1 | AA12: L3 | AB12: =IF(OR(Z12="",AA12=""),"",IF(VALUE(MID(AA12,2,1))>VALUE(MID(Z12,2,1)),"Upward (observables)",IF(VALUE(MID(AA12,2,1))<VALUE(MID(Z12,2,1)),"Downward (config / keys / sync)","Within layer"))) -> Upward (observables) | AC12: =IF(OR(Z12="",AA12=""),"",IF(AND(MIN(VALUE(MID(Z12,2,1)),VALUE(MID(AA12,2,1)))<=1,MAX(VALUE(MID(Z12,2,1)),VALUE(MID(AA12,2,1)))>=2),"✓","")) -> ✓ | AD12: =IF(OR(Z12="",AA12=""),"",IF(AND(MIN(VALUE(MID(Z12,2,1)),VALUE(MID(AA12,2,1)))<=2,MAX(VALUE(MID(Z12,2,1)),VALUE(MID(AA12,2,1)))>=3),"✓","")) -> ✓ | AE12: =IF(OR(Z12="",AA12=""),"",IF(AND(MIN(VALUE(MID(Z12,2,1)),VALUE(MID(AA12,2,1)))<=3,MAX(VALUE(MID(Z12,2,1)),VALUE(MID(AA12,2,1)))>=4),"✓","")) | AF12: None | AH12: =COUNTIF('CVE Register'!$P$6:$P$300,A12) -> 0 | AI12: M17 | AK12: Original review set | AL12: A1.1 | AM12: Bound threats: T1.02 | AN12: L1 > L2 > L3 > L4 (4 of 4 layers) L1: [A1.1], A1.3, A1.4, A1.7 | L2: A2.1, A2.2, A2.4 | L3: A3.1, A3.3, A3.4, A3.5, A3.6 | L4: A4.5, A4.6 Boundaries to first check A3.4/A3.5: 2 | to ATM A4.6: 3
A13: 8 | B13: Verifying ADS-B Navigation Information Through Doppler Shift Measurements | C13: Ghose & Lazos (2015) | D13: IEEE/AIAA Digital Avionics Systems Conference (DASC) | E13: Not ICORE-ranked | F13: Avionics DASC not listed (ICORE 'DASC' is a different conference) | G13: Single-emitter spoofer | H13: Protocol flaw: self-reported position / velocity unverified | I13: Position and velocity spoofing | J13: Simulated / Proof-of-Concept | K13: Simulation | L13: Doppler shifts observed at receivers can verify claimed motion; simulation shows spoofed tracks are detected. | M13: Ghose2015Doppler | N13: Aviation surveillance (ADS-B / MLAT) | O13: E1 | P13: Table 1, [37] | Q13: Peer-reviewed conference | R13: =IF(LEFT(Q13,13)="Peer-reviewed","Yes","No") -> Yes | S13: =C13&". "&CHAR(34)&B13&CHAR(34)&". "&D13&"." -> Ghose & Lazos (2015). "Verifying ADS-B Navigation Information Through Doppler Shift Measurements". IEEE/AIAA Digital Avionics Systems Conference (DASC). | T13: https://doi.org/10.1109/DASC.2015.7311412 | U13: DOI metadata checked 13 Oct 2026 (OpenAlex): title matches | V13: Protocol design gap | W13: Spoofing / injection | X13: Position and velocity spoofing checked against receiver-observed Doppler shift (simulation). | Y13: L1 · Transponder signals & satellite receivers (ADS-B / Mode S) | Z13: L1 | AA13: L3 | AB13: =IF(OR(Z13="",AA13=""),"",IF(VALUE(MID(AA13,2,1))>VALUE(MID(Z13,2,1)),"Upward (observables)",IF(VALUE(MID(AA13,2,1))<VALUE(MID(Z13,2,1)),"Downward (config / keys / sync)","Within layer"))) -> Upward (observables) | AC13: =IF(OR(Z13="",AA13=""),"",IF(AND(MIN(VALUE(MID(Z13,2,1)),VALUE(MID(AA13,2,1)))<=1,MAX(VALUE(MID(Z13,2,1)),VALUE(MID(AA13,2,1)))>=2),"✓","")) -> ✓ | AD13: =IF(OR(Z13="",AA13=""),"",IF(AND(MIN(VALUE(MID(Z13,2,1)),VALUE(MID(AA13,2,1)))<=2,MAX(VALUE(MID(Z13,2,1)),VALUE(MID(AA13,2,1)))>=3),"✓","")) -> ✓ | AE13: =IF(OR(Z13="",AA13=""),"",IF(AND(MIN(VALUE(MID(Z13,2,1)),VALUE(MID(AA13,2,1)))<=3,MAX(VALUE(MID(Z13,2,1)),VALUE(MID(AA13,2,1)))>=4),"✓","")) | AF13: None | AH13: =COUNTIF('CVE Register'!$P$6:$P$300,A13) -> 0 | AI13: M16 | AJ13: FOA-based check, complementary to TDOA. | AK13: Original review set | AL13: A1.4 | AM13: Bound threats: T1.09 | AN13: L1 > L2 > L3 > L4 (4 of 4 layers) L1: [A1.4], A1.7 | L2: A2.1, A2.2, A2.4 | L3: A3.1, A3.3, A3.4, A3.5, A3.6 | L4: A4.5, A4.6 Boundaries to first check A3.4/A3.5: 2 | to ATM A4.6: 3
A14: 9 | B14: Secure Motion Verification Using the Doppler Effect | C14: Schäfer et al. (2016) | D14: ACM WiSec | E14: ICORE2026 B | F14: ICORE: ACM_WiSec | G14: Motion spoofer including stronger attacker models | H14: Protocol flaw: self-reported kinematics unauthenticated | I14: Position and velocity spoofing | J14: Simulated / Proof-of-Concept | K14: Simulated attacks | L14: Doppler-based verification detects spoofed motion claims, complementing TDOA approaches. | M14: Schafer2016Doppler | N14: Aviation surveillance (ADS-B / MLAT) | O14: E1 | P14: Table 1, [38] | Q14: Peer-reviewed conference | R14: =IF(LEFT(Q14,13)="Peer-reviewed","Yes","No") -> Yes | S14: =C14&". "&CHAR(34)&B14&CHAR(34)&". "&D14&"." -> Schäfer et al. (2016). "Secure Motion Verification Using the Doppler Effect". ACM WiSec. | T14: https://doi.org/10.1145/2939918.2939920 | U14: DOI metadata checked 13 Oct 2026 (OpenAlex): title matches | V14: Protocol design gap | W14: Spoofing / injection | X14: Spoofed motion claims checked against Doppler measurements across receivers (simulation). | Y14: L1 · Transponder signals & satellite receivers (ADS-B / Mode S) | Z14: L1 | AA14: L3 | AB14: =IF(OR(Z14="",AA14=""),"",IF(VALUE(MID(AA14,2,1))>VALUE(MID(Z14,2,1)),"Upward (observables)",IF(VALUE(MID(AA14,2,1))<VALUE(MID(Z14,2,1)),"Downward (config / keys / sync)","Within layer"))) -> Upward (observables) | AC14: =IF(OR(Z14="",AA14=""),"",IF(AND(MIN(VALUE(MID(Z14,2,1)),VALUE(MID(AA14,2,1)))<=1,MAX(VALUE(MID(Z14,2,1)),VALUE(MID(AA14,2,1)))>=2),"✓","")) -> ✓ | AD14: =IF(OR(Z14="",AA14=""),"",IF(AND(MIN(VALUE(MID(Z14,2,1)),VALUE(MID(AA14,2,1)))<=2,MAX(VALUE(MID(Z14,2,1)),VALUE(MID(AA14,2,1)))>=3),"✓","")) -> ✓ | AE14: =IF(OR(Z14="",AA14=""),"",IF(AND(MIN(VALUE(MID(Z14,2,1)),VALUE(MID(AA14,2,1)))<=3,MAX(VALUE(MID(Z14,2,1)),VALUE(MID(AA14,2,1)))>=4),"✓","")) | AF14: None | AH14: =COUNTIF('CVE Register'!$P$6:$P$300,A14) -> 0 | AI14: M16 | AK14: Original review set | AL14: A1.4 | AM14: Bound threats: T1.09 | AN14: L1 > L2 > L3 > L4 (4 of 4 layers) L1: [A1.4], A1.7 | L2: A2.1, A2.2, A2.4 | L3: A3.1, A3.3, A3.4, A3.5, A3.6 | L4: A4.5, A4.6 Boundaries to first check A3.4/A3.5: 2 | to ATM A4.6: 3
A15: 10 | B15: Crowd-GPS-Sec: Leveraging Crowdsourcing to Detect and Localize GPS Spoofing Attacks | C15: Jansen et al. (2018) | D15: IEEE Symposium on Security and Privacy (S&P) | E15: ICORE2026 A* | F15: ICORE: SP | G15: GPS spoofer affecting aircraft in an area | H15: Design gap: unauthenticated civil GNSS | I15: GPS spoofing | J15: Simulated / Proof-of-Concept | K15: Spoofing simulated on real ADS-B data | L15: Crowdsourced ADS-B / MLAT data can detect GPS spoofing within seconds and localise the spoofer. | M15: Jansen2018CrowdGPSSec | N15: GNSS | O15: E1 | P15: Table 1, [39] | Q15: Peer-reviewed conference | R15: =IF(LEFT(Q15,13)="Peer-reviewed","Yes","No") -> Yes | S15: =C15&". "&CHAR(34)&B15&CHAR(34)&". "&D15&"." -> Jansen et al. (2018). "Crowd-GPS-Sec: Leveraging Crowdsourcing to Detect and Localize GPS Spoofing Attacks". IEEE Symposium on Security and Privacy (S&P). | T15: https://doi.org/10.1109/SP.2018.00012 | U15: DOI metadata checked 13 Oct 2026 (OpenAlex): title matches | V15: Protocol design gap | W15: Spoofing / injection | X15: GPS spoofing of aircraft detected and the spoofer localised from crowdsourced ADS-B/MLAT data. | Y15: L1 · GNSS receiver / onboard clock | Z15: L1 | AA15: L3 | AB15: =IF(OR(Z15="",AA15=""),"",IF(VALUE(MID(AA15,2,1))>VALUE(MID(Z15,2,1)),"Upward (observables)",IF(VALUE(MID(AA15,2,1))<VALUE(MID(Z15,2,1)),"Downward (config / keys / sync)","Within layer"))) -> Upward (observables) | AC15: =IF(OR(Z15="",AA15=""),"",IF(AND(MIN(VALUE(MID(Z15,2,1)),VALUE(MID(AA15,2,1)))<=1,MAX(VALUE(MID(Z15,2,1)),VALUE(MID(AA15,2,1)))>=2),"✓","")) -> ✓ | AD15: =IF(OR(Z15="",AA15=""),"",IF(AND(MIN(VALUE(MID(Z15,2,1)),VALUE(MID(AA15,2,1)))<=2,MAX(VALUE(MID(Z15,2,1)),VALUE(MID(AA15,2,1)))>=3),"✓","")) -> ✓ | AE15: =IF(OR(Z15="",AA15=""),"",IF(AND(MIN(VALUE(MID(Z15,2,1)),VALUE(MID(AA15,2,1)))<=3,MAX(VALUE(MID(Z15,2,1)),VALUE(MID(AA15,2,1)))>=4),"✓","")) | AF15: Direct | AH15: =COUNTIF('CVE Register'!$P$6:$P$300,A15) -> 0 | AI15: M18; M01 | AK15: Original review set | AL15: A1.2, A1.5 | AM15: Group default (not bound to a catalogue threat) | AN15: L1 > L2 > L3 > L4 (4 of 4 layers) L1: [A1.2], [A1.5], A1.4, A1.7 | L2: A2.1, A2.2, A2.4 | L3: A3.1, A3.2, A3.3, A3.4, A3.5, A3.6 | L4: A4.5, A4.6 Boundaries to first check A3.4/A3.5: 2 | to ATM A4.6: 3
A16: 11 | B16: GNSS-WASP: GNSS Wide Area SPoofing | C16: Tibaldo et al. (2025) | D16: USENIX Security Symposium | E16: ICORE2026 A* | F16: ICORE: USENIX-Security | G16: Advanced wide-area spoofer targeting multiple receivers | H16: Design gap: unauthenticated GNSS; multi-receiver detection assumes spatial inconsistency | I16: Coordinated wide-area spoofing evading detection | J16: Simulated / Proof-of-Concept | K16: Proof-of-concept evaluation | L16: Spoofing can keep receivers' relative positions consistent, undermining crowdsourced and multi-receiver detection. | M16: Tibaldo2025GNSSWASP | N16: GNSS | O16: E1 | P16: Table 1, [40] | Q16: Peer-reviewed conference | R16: =IF(LEFT(Q16,13)="Peer-reviewed","Yes","No") -> Yes | S16: =C16&". "&CHAR(34)&B16&CHAR(34)&". "&D16&"." -> Tibaldo et al. (2025). "GNSS-WASP: GNSS Wide Area SPoofing". USENIX Security Symposium. | T16: https://www.usenix.org/conference/usenixsecurity25/presentation/tibaldo | U16: Page fetched 13 Oct 2026: title matches | V16: Protocol design gap | W16: Spoofing / injection | X16: Wide-area GNSS spoofing that preserves receivers' relative geometry to evade multi-receiver detection. | Y16: L1 · GNSS receiver / onboard clock | Z16: L1 | AA16: L1 | AB16: =IF(OR(Z16="",AA16=""),"",IF(VALUE(MID(AA16,2,1))>VALUE(MID(Z16,2,1)),"Upward (observables)",IF(VALUE(MID(AA16,2,1))<VALUE(MID(Z16,2,1)),"Downward (config / keys / sync)","Within layer"))) -> Within layer | AC16: =IF(OR(Z16="",AA16=""),"",IF(AND(MIN(VALUE(MID(Z16,2,1)),VALUE(MID(AA16,2,1)))<=1,MAX(VALUE(MID(Z16,2,1)),VALUE(MID(AA16,2,1)))>=2),"✓","")) | AD16: =IF(OR(Z16="",AA16=""),"",IF(AND(MIN(VALUE(MID(Z16,2,1)),VALUE(MID(AA16,2,1)))<=2,MAX(VALUE(MID(Z16,2,1)),VALUE(MID(AA16,2,1)))>=3),"✓","")) | AE16: =IF(OR(Z16="",AA16=""),"",IF(AND(MIN(VALUE(MID(Z16,2,1)),VALUE(MID(AA16,2,1)))<=3,MAX(VALUE(MID(Z16,2,1)),VALUE(MID(AA16,2,1)))>=4),"✓","")) | AF16: Direct | AH16: =COUNTIF('CVE Register'!$P$6:$P$300,A16) -> 0 | AI16: M01; M18; M19 | AJ16: Limits crowdsourced / multi-receiver detection (M18). | AK16: Original review set | AL16: A1.2, A1.5 | AM16: Group default (not bound to a catalogue threat) | AN16: L1 > L2 > L3 > L4 (4 of 4 layers) L1: [A1.2], [A1.5], A1.4, A1.7 | L2: A2.1, A2.2, A2.4 | L3: A3.1, A3.2, A3.3, A3.4, A3.5, A3.6 | L4: A4.5, A4.6 Boundaries to first check A3.4/A3.5: 2 | to ATM A4.6: 3
A17: 12 | B17: Detecting Injection Attacks in ADS-B Devices Using RNN-Based Models | C17: Khoei et al. (2024) | D17: Integrated Communications, Navigation and Surveillance Conf. (ICNS) | E17: Not ICORE-ranked | F17: Not in ICORE2026 list | G17: SDR injector | H17: Protocol flaw: unauthenticated broadcast | I17: Message injection | J17: Simulated / Proof-of-Concept | K17: Synthetic attack data | L17: RNN-based models detect injected ADS-B messages on datasets with simulated attacks. | M17: Khoei2024RNNADSB | N17: Aviation surveillance (ADS-B / MLAT) | O17: E1 | P17: Table 1, [41] | Q17: Peer-reviewed conference | R17: =IF(LEFT(Q17,13)="Peer-reviewed","Yes","No") -> Yes | S17: =C17&". "&CHAR(34)&B17&CHAR(34)&". "&D17&"." -> Khoei et al. (2024). "Detecting Injection Attacks in ADS-B Devices Using RNN-Based Models". Integrated Communications, Navigation and Surveillance Conf. (ICNS). | T17: https://par.nsf.gov/biblio/10564790 | U17: Page fetched 13 Oct 2026: title matches (NSF PAR record; no DOI shown) | V17: Protocol design gap | W17: Spoofing / injection | X17: Injected ADS-B messages detected by RNN models on synthetic attack data. | Y17: L1 · Transponder signals & satellite receivers (ADS-B / Mode S) | Z17: L1 | AA17: L3 | AB17: =IF(OR(Z17="",AA17=""),"",IF(VALUE(MID(AA17,2,1))>VALUE(MID(Z17,2,1)),"Upward (observables)",IF(VALUE(MID(AA17,2,1))<VALUE(MID(Z17,2,1)),"Downward (config / keys / sync)","Within layer"))) -> Upward (observables) | AC17: =IF(OR(Z17="",AA17=""),"",IF(AND(MIN(VALUE(MID(Z17,2,1)),VALUE(MID(AA17,2,1)))<=1,MAX(VALUE(MID(Z17,2,1)),VALUE(MID(AA17,2,1)))>=2),"✓","")) -> ✓ | AD17: =IF(OR(Z17="",AA17=""),"",IF(AND(MIN(VALUE(MID(Z17,2,1)),VALUE(MID(AA17,2,1)))<=2,MAX(VALUE(MID(Z17,2,1)),VALUE(MID(AA17,2,1)))>=3),"✓","")) -> ✓ | AE17: =IF(OR(Z17="",AA17=""),"",IF(AND(MIN(VALUE(MID(Z17,2,1)),VALUE(MID(AA17,2,1)))<=3,MAX(VALUE(MID(Z17,2,1)),VALUE(MID(AA17,2,1)))>=4),"✓","")) | AF17: None | AH17: =COUNTIF('CVE Register'!$P$6:$P$300,A17) -> 0 | AI17: M17 | AK17: Original review set | AL17: A1.1, A1.3 | AM17: Group default (not bound to a catalogue threat) | AN17: L1 > L2 > L3 > L4 (4 of 4 layers) L1: [A1.1], [A1.3], A1.4, A1.7 | L2: A2.1, A2.2, A2.4 | L3: A3.1, A3.3, A3.4, A3.5, A3.6 | L4: A4.5, A4.6 Boundaries to first check A3.4/A3.5: 2 | to ATM A4.6: 3
A18: 13 | B18: ICARUS: Attacking Low Earth Orbit Satellite Networks | C18: Giuliari et al. (2021) | D18: USENIX Annual Technical Conference (ATC) | E18: ICORE2026 A | F18: ICORE: USENIX (ATC) | G18: Attacker controlling distributed legitimate terminals or a botnet | H18: Architectural weakness: predictable LEO topology and shared links | I18: Link-flooding DDoS | J18: Simulated / Proof-of-Concept | K18: Constellation simulation | L18: Predictable LEO topology lets attackers target bottleneck links cheaply; shown on Starlink-like constellation simulations. | M18: Giuliari2021ICARUS | N18: Satellite & space | O18: E1 | P18: Table 3, [54] | Q18: Peer-reviewed conference | R18: =IF(LEFT(Q18,13)="Peer-reviewed","Yes","No") -> Yes | S18: =C18&". "&CHAR(34)&B18&CHAR(34)&". "&D18&"." -> Giuliari et al. (2021). "ICARUS: Attacking Low Earth Orbit Satellite Networks". USENIX Annual Technical Conference (ATC). | T18: https://www.usenix.org/conference/atc21/presentation/giuliari | U18: Page fetched 13 Oct 2026: title matches | V18: Architectural weakness | W18: Jamming / denial of service | X18: Link-flooding DDoS exploiting predictable LEO topology to congest bottleneck links (simulation). | Y18: L2 · ISLs & downlinks (observables in transit) | Z18: L2 | AA18: L2 | AB18: =IF(OR(Z18="",AA18=""),"",IF(VALUE(MID(AA18,2,1))>VALUE(MID(Z18,2,1)),"Upward (observables)",IF(VALUE(MID(AA18,2,1))<VALUE(MID(Z18,2,1)),"Downward (config / keys / sync)","Within layer"))) -> Within layer | AC18: =IF(OR(Z18="",AA18=""),"",IF(AND(MIN(VALUE(MID(Z18,2,1)),VALUE(MID(AA18,2,1)))<=1,MAX(VALUE(MID(Z18,2,1)),VALUE(MID(AA18,2,1)))>=2),"✓","")) | AD18: =IF(OR(Z18="",AA18=""),"",IF(AND(MIN(VALUE(MID(Z18,2,1)),VALUE(MID(AA18,2,1)))<=2,MAX(VALUE(MID(Z18,2,1)),VALUE(MID(AA18,2,1)))>=3),"✓","")) | AE18: =IF(OR(Z18="",AA18=""),"",IF(AND(MIN(VALUE(MID(Z18,2,1)),VALUE(MID(AA18,2,1)))<=3,MAX(VALUE(MID(Z18,2,1)),VALUE(MID(AA18,2,1)))>=4),"✓","")) | AF18: None | AH18: =COUNTIF('CVE Register'!$P$6:$P$300,A18) -> 0 | AI18: M09; M25 | AJ18: Could starve ISL/downlink capacity used for TOA transport. | AK18: Original review set | AL18: A1.1, A1.7, A2.2 | AM18: Bound threats: T1.08, T1.16, T2.04 | AN18: L1 > L2 > L3 > L4 (4 of 4 layers) L1: [A1.1], [A1.7], A1.3, A1.4 | L2: [A2.2], A2.1, A2.4 | L3: A3.1, A3.3, A3.4, A3.5, A3.6 | L4: A4.5, A4.6 Boundaries to first check A3.4/A3.5: 1 | to ATM A4.6: 2
A19: 14 | B19: Watch This Space: Securing Satellite Communication through Resilient Transmitter Fingerprinting | C19: Smailes et al. (2023) | D19: ACM CCS | E19: ICORE2026 A* | F19: ICORE: CCS | G19: SDR attacker impersonating satellite transmissions | H19: Protocol flaw: unauthenticated satellite downlinks | I19: Spoofing; replay | J19: Simulated / Proof-of-Concept | K19: Emulated SDR attacks on real Iridium signals | L19: RF fingerprinting on real Iridium signals reliably distinguishes genuine from spoofed transmitters. | M19: Smailes2023Fingerprinting | N19: Satellite & space | O19: E1 | P19: Table 3, [55] | Q19: Peer-reviewed conference | R19: =IF(LEFT(Q19,13)="Peer-reviewed","Yes","No") -> Yes | S19: =C19&". "&CHAR(34)&B19&CHAR(34)&". "&D19&"." -> Smailes et al. (2023). "Watch This Space: Securing Satellite Communication through Resilient Transmitter Fingerprinting". ACM CCS. | T19: https://doi.org/10.1145/3576915.3623135 | U19: DOI metadata checked 13 Oct 2026 (OpenAlex): title matches | V19: Protocol design gap | W19: Spoofing / injection | X19: Spoofed or replayed satellite downlink transmissions, countered by RF fingerprinting of real Iridium signals. | Y19: L1 · Satellite & ground-station RF receivers | Z19: L1 | AA19: L3 | AB19: =IF(OR(Z19="",AA19=""),"",IF(VALUE(MID(AA19,2,1))>VALUE(MID(Z19,2,1)),"Upward (observables)",IF(VALUE(MID(AA19,2,1))<VALUE(MID(Z19,2,1)),"Downward (config / keys / sync)","Within layer"))) -> Upward (observables) | AC19: =IF(OR(Z19="",AA19=""),"",IF(AND(MIN(VALUE(MID(Z19,2,1)),VALUE(MID(AA19,2,1)))<=1,MAX(VALUE(MID(Z19,2,1)),VALUE(MID(AA19,2,1)))>=2),"✓","")) -> ✓ | AD19: =IF(OR(Z19="",AA19=""),"",IF(AND(MIN(VALUE(MID(Z19,2,1)),VALUE(MID(AA19,2,1)))<=2,MAX(VALUE(MID(Z19,2,1)),VALUE(MID(AA19,2,1)))>=3),"✓","")) -> ✓ | AE19: =IF(OR(Z19="",AA19=""),"",IF(AND(MIN(VALUE(MID(Z19,2,1)),VALUE(MID(AA19,2,1)))<=3,MAX(VALUE(MID(Z19,2,1)),VALUE(MID(AA19,2,1)))>=4),"✓","")) | AF19: None | AH19: =COUNTIF('CVE Register'!$P$6:$P$300,A19) -> 0 | AI19: M17; M04 | AK19: Original review set | AL19: A2.1 | AM19: Bound threats: T2.02 | AN19: L1 > L2 > L3 > L4 (4 of 4 layers) L1: A1.7 | L2: [A2.1], A2.2, A2.4 | L3: A3.1, A3.3, A3.4, A3.5, A3.6 | L4: A4.5, A4.6 Boundaries to first check A3.4/A3.5: 1 | to ATM A4.6: 2
A20: 15 | B20: Space Odyssey: An Experimental Software Security Analysis of Satellites | C20: Willbold et al. (2023) | D20: IEEE Symposium on Security and Privacy (S&P) | E20: ICORE2026 A* | F20: ICORE: SP | G20: Remote attacker with radio access to the uplink | H20: Software bugs and missing protections in on-board firmware | I20: Satellite hijack via memory corruption and unprotected telecommand | J20: Simulated / Proof-of-Concept | K20: Real flight firmware, emulated environment | L20: Analysed firmware of three real satellites, found exploitable flaws enabling takeover, and surveyed practitioners showing security is rarely prioritised. | M20: Willbold2023SpaceOdyssey | N20: Satellite & space | O20: E1 | P20: Table 3, [52] | Q20: Peer-reviewed conference | R20: =IF(LEFT(Q20,13)="Peer-reviewed","Yes","No") -> Yes | S20: =C20&". "&CHAR(34)&B20&CHAR(34)&". "&D20&"." -> Willbold et al. (2023). "Space Odyssey: An Experimental Software Security Analysis of Satellites". IEEE Symposium on Security and Privacy (S&P). | T20: https://ieeexplore.ieee.org/document/10351029 | U20: Search index 13 Oct 2026: page title matches, page not fetchable | V20: Implementation flaw | W20: Software exploitation / takeover | X20: Exploitable on-board firmware flaws and unprotected telecommand enabling satellite takeover (emulated). | Y20: L1 · Satellite platform & flight software | Z20: L1 | AA20: L1 | AB20: =IF(OR(Z20="",AA20=""),"",IF(VALUE(MID(AA20,2,1))>VALUE(MID(Z20,2,1)),"Upward (observables)",IF(VALUE(MID(AA20,2,1))<VALUE(MID(Z20,2,1)),"Downward (config / keys / sync)","Within layer"))) -> Within layer | AC20: =IF(OR(Z20="",AA20=""),"",IF(AND(MIN(VALUE(MID(Z20,2,1)),VALUE(MID(AA20,2,1)))<=1,MAX(VALUE(MID(Z20,2,1)),VALUE(MID(AA20,2,1)))>=2),"✓","")) | AD20: =IF(OR(Z20="",AA20=""),"",IF(AND(MIN(VALUE(MID(Z20,2,1)),VALUE(MID(AA20,2,1)))<=2,MAX(VALUE(MID(Z20,2,1)),VALUE(MID(AA20,2,1)))>=3),"✓","")) | AE20: =IF(OR(Z20="",AA20=""),"",IF(AND(MIN(VALUE(MID(Z20,2,1)),VALUE(MID(AA20,2,1)))<=3,MAX(VALUE(MID(Z20,2,1)),VALUE(MID(AA20,2,1)))>=4),"✓","")) | AF20: None | AH20: =COUNTIF('CVE Register'!$P$6:$P$300,A20) -> 0 | AI20: M24; M04 | AJ20: Talk version: Black Hat USA 2023 'Houston, We Have a Problem'. | AK20: Original review set | AL20: A1.6, A2.5 | AM20: Bound threats: T1.12, T1.13, T1.14, T2.11 | AN20: L1 > L2 > L3 > L4 (4 of 4 layers) L1: [A1.6], A1.4†, A1.5†, A1.7† | L2: [A2.5], A2.1†, A2.2†, A2.4† | L3: A3.1†, A3.2†, A3.3†, A3.4†, A3.5†, A3.6† | L4: A4.5†, A4.6† Boundaries to first check A3.4/A3.5: 2 | to ATM A4.6: 3
A21: 16 | B21: Stargaze: A LEO Constellation Emulator for Security Experimentation | C21: Kon, Barradas & Chen (2022) | D21: ACM CPSIoTSec Workshop | E21: Not ICORE-ranked | F21: Workshop; not in ICORE2026 list | G21: Generic network attacker | H21: Not applicable (platform paper) | I21: Network attacks on LEO via emulation | J21: Simulated / Proof-of-Concept | K21: Emulator platform | L21: Provides an emulation platform for reproducible attack experiments on LEO constellations. | M21: Kon2022Stargaze | N21: Satellite & space | O21: E1 | P21: Table 3, [76] | Q21: Peer-reviewed workshop | R21: =IF(LEFT(Q21,13)="Peer-reviewed","Yes","No") -> Yes | S21: =C21&". "&CHAR(34)&B21&CHAR(34)&". "&D21&"." -> Kon, Barradas & Chen (2022). "Stargaze: A LEO Constellation Emulator for Security Experimentation". ACM CPSIoTSec Workshop. | T21: https://par.nsf.gov/biblio/10406778 | U21: Page fetched 13 Oct 2026: title matches (NSF PAR record; no DOI shown) | V21: Architectural weakness | W21: Jamming / denial of service | X21: Emulation platform for reproducible network attacks on LEO constellations. | Y21: L2 · ISLs & downlinks (observables in transit) | Z21: L2 | AA21: L2 | AB21: =IF(OR(Z21="",AA21=""),"",IF(VALUE(MID(AA21,2,1))>VALUE(MID(Z21,2,1)),"Upward (observables)",IF(VALUE(MID(AA21,2,1))<VALUE(MID(Z21,2,1)),"Downward (config / keys / sync)","Within layer"))) -> Within layer | AC21: =IF(OR(Z21="",AA21=""),"",IF(AND(MIN(VALUE(MID(Z21,2,1)),VALUE(MID(AA21,2,1)))<=1,MAX(VALUE(MID(Z21,2,1)),VALUE(MID(AA21,2,1)))>=2),"✓","")) | AD21: =IF(OR(Z21="",AA21=""),"",IF(AND(MIN(VALUE(MID(Z21,2,1)),VALUE(MID(AA21,2,1)))<=2,MAX(VALUE(MID(Z21,2,1)),VALUE(MID(AA21,2,1)))>=3),"✓","")) | AE21: =IF(OR(Z21="",AA21=""),"",IF(AND(MIN(VALUE(MID(Z21,2,1)),VALUE(MID(AA21,2,1)))<=3,MAX(VALUE(MID(Z21,2,1)),VALUE(MID(AA21,2,1)))>=4),"✓","")) | AF21: None | AH21: =COUNTIF('CVE Register'!$P$6:$P$300,A21) -> 0 | AI21: M09 | AJ21: Platform paper. | AK21: Original review set | AL21: A1.1, A2.2 | AM21: Bound threats: T1.08, T2.04 | AN21: L1 > L2 > L3 > L4 (4 of 4 layers) L1: [A1.1], A1.3, A1.4, A1.7 | L2: [A2.2], A2.1, A2.4 | L3: A3.1, A3.3, A3.4, A3.5, A3.6 | L4: A4.5, A4.6 Boundaries to first check A3.4/A3.5: 1 | to ATM A4.6: 2
A22: 17 | B22: False Data Injection Attacks against State Estimation in Electric Power Grids | C22: Liu, Ning & Reiter (2009; extended 2011) | D22: ACM CCS (extended in ACM TISSEC) | E22: ICORE2026 A* | F22: ICORE: CCS (2009 version) | G22: Attacker knowing system configuration and controlling some meters | H22: Design gap: residual-based bad-data detection | I22: Stealthy false data injection | J22: Simulated / Proof-of-Concept | K22: IEEE test bus systems | L22: Attackers with knowledge of system configuration can inject errors that bypass residual-based detection; strong analogue for MLAT solver integrity attacks. | M22: Liu2009FDI / Liu2011FDI | N22: State estimation | O22: E1 | P22: §2.5.2 [72] | Q22: Peer-reviewed conference | R22: =IF(LEFT(Q22,13)="Peer-reviewed","Yes","No") -> Yes | S22: =C22&". "&CHAR(34)&B22&CHAR(34)&". "&D22&"." -> Liu, Ning & Reiter (2009; extended 2011). "False Data Injection Attacks against State Estimation in Electric Power Grids". ACM CCS (extended in ACM TISSEC). | T22: https://doi.org/10.1145/1653662.1653666 | U22: DOI metadata checked 13 Oct 2026 (OpenAlex): title matches; TISSEC version doi:10.1145/1952982.1952995 also checked | V22: Estimation / verification design limit | W22: Estimation / data manipulation | X22: Stealthy false-data injection that bypasses residual-based bad-data detection (analogue for MLAT solver integrity). | Y22: L2 · Measurements feeding the estimator | Z22: L2 | AA22: L3 | AB22: =IF(OR(Z22="",AA22=""),"",IF(VALUE(MID(AA22,2,1))>VALUE(MID(Z22,2,1)),"Upward (observables)",IF(VALUE(MID(AA22,2,1))<VALUE(MID(Z22,2,1)),"Downward (config / keys / sync)","Within layer"))) -> Upward (observables) | AC22: =IF(OR(Z22="",AA22=""),"",IF(AND(MIN(VALUE(MID(Z22,2,1)),VALUE(MID(AA22,2,1)))<=1,MAX(VALUE(MID(Z22,2,1)),VALUE(MID(AA22,2,1)))>=2),"✓","")) | AD22: =IF(OR(Z22="",AA22=""),"",IF(AND(MIN(VALUE(MID(Z22,2,1)),VALUE(MID(AA22,2,1)))<=2,MAX(VALUE(MID(Z22,2,1)),VALUE(MID(AA22,2,1)))>=3),"✓","")) -> ✓ | AE22: =IF(OR(Z22="",AA22=""),"",IF(AND(MIN(VALUE(MID(Z22,2,1)),VALUE(MID(AA22,2,1)))<=3,MAX(VALUE(MID(Z22,2,1)),VALUE(MID(AA22,2,1)))>=4),"✓","")) | AF22: None | AH22: =COUNTIF('CVE Register'!$P$6:$P$300,A22) -> 0 | AI22: M20 | AJ22: Analogue domain (power grid). | AK22: Original review set | AL22: A2.1 | AM22: Bound threats: T2.01 | AN22: L1 > L2 > L3 > L4 (4 of 4 layers) L1: A1.7 | L2: [A2.1], A2.2, A2.4 | L3: A3.1, A3.3, A3.4, A3.5, A3.6 | L4: A4.5, A4.6 Boundaries to first check A3.4/A3.5: 1 | to ATM A4.6: 2
A23: 18 | B23: False Data Injection Attacks in Control Systems | C23: Mo & Sinopoli (2010) | D23: Workshop on Secure Control Systems (SCS) | E23: Not ICORE-ranked | F23: Workshop; not in ICORE2026 list | G23: Attacker compromising a subset of sensors | H23: Design gap: Kalman filter with chi-square detector | I23: Stealthy false data injection | J23: Simulated / Proof-of-Concept | K23: Numerical example | L23: Derived conditions under which an attacker can drive estimation error unboundedly without triggering the chi-square detector. | M23: Mo2010FDIControl | N23: State estimation | O23: E1 | P23: §2.5.2 [73] | Q23: Peer-reviewed workshop | R23: =IF(LEFT(Q23,13)="Peer-reviewed","Yes","No") -> Yes | S23: =C23&". "&CHAR(34)&B23&CHAR(34)&". "&D23&"." -> Mo & Sinopoli (2010). "False Data Injection Attacks in Control Systems". Workshop on Secure Control Systems (SCS). | T23: https://ptolemy.berkeley.edu/projects/truststc/conferences/10/CPSWeek/papers/scs1_paper_7.pdf | U23: Page fetched 13 Oct 2026: title matches (author PDF on workshop site) | V23: Estimation / verification design limit | W23: Estimation / data manipulation | X23: Sensor-subset injection that grows Kalman-filter error while evading the chi-square detector. | Y23: L2 · Measurements feeding the estimator | Z23: L2 | AA23: L3 | AB23: =IF(OR(Z23="",AA23=""),"",IF(VALUE(MID(AA23,2,1))>VALUE(MID(Z23,2,1)),"Upward (observables)",IF(VALUE(MID(AA23,2,1))<VALUE(MID(Z23,2,1)),"Downward (config / keys / sync)","Within layer"))) -> Upward (observables) | AC23: =IF(OR(Z23="",AA23=""),"",IF(AND(MIN(VALUE(MID(Z23,2,1)),VALUE(MID(AA23,2,1)))<=1,MAX(VALUE(MID(Z23,2,1)),VALUE(MID(AA23,2,1)))>=2),"✓","")) | AD23: =IF(OR(Z23="",AA23=""),"",IF(AND(MIN(VALUE(MID(Z23,2,1)),VALUE(MID(AA23,2,1)))<=2,MAX(VALUE(MID(Z23,2,1)),VALUE(MID(AA23,2,1)))>=3),"✓","")) -> ✓ | AE23: =IF(OR(Z23="",AA23=""),"",IF(AND(MIN(VALUE(MID(Z23,2,1)),VALUE(MID(AA23,2,1)))<=3,MAX(VALUE(MID(Z23,2,1)),VALUE(MID(AA23,2,1)))>=4),"✓","")) | AF23: None | AH23: =COUNTIF('CVE Register'!$P$6:$P$300,A23) -> 0 | AI23: M20 | AJ23: Analogue for EKF/IMM integrity monitoring. | AK23: Original review set | AL23: A2.1 | AM23: Bound threats: T2.01 | AN23: L1 > L2 > L3 > L4 (4 of 4 layers) L1: A1.7 | L2: [A2.1], A2.2, A2.4 | L3: A3.1, A3.3, A3.4, A3.5, A3.6 | L4: A4.5, A4.6 Boundaries to first check A3.4/A3.5: 1 | to ATM A4.6: 2
A24: 19 | B24: Time Synchronization Attack in Smart Grid: Impact and Analysis | C24: Zhang et al. (2013) | D24: IEEE Transactions on Smart Grid | E24: SJR 2025 Q1 | F24: SCImago: IEEE Trans. Smart Grid | G24: GPS spoofer targeting PMU timing | H24: Design gap: timestamps depend on unauthenticated GPS | I24: Time synchronisation attack | J24: Simulated / Proof-of-Concept | K24: Simulation | L24: Spoofed GPS time corrupts PMU phase measurements, degrading fault detection / localisation and stability monitoring; analogue for the cross-cutting timing dependency. | M24: Zhang2013TSA | N24: Timing | O24: E1 | P24: §2.5.2 [74] | Q24: Peer-reviewed journal | R24: =IF(LEFT(Q24,13)="Peer-reviewed","Yes","No") -> Yes | S24: =C24&". "&CHAR(34)&B24&CHAR(34)&". "&D24&"." -> Zhang et al. (2013). "Time Synchronization Attack in Smart Grid: Impact and Analysis". IEEE Transactions on Smart Grid. | T24: https://doi.org/10.1109/TSG.2012.2227342 | U24: DOI metadata checked 13 Oct 2026 (OpenAlex): title matches | V24: Protocol design gap | W24: Timing & synchronisation attack | X24: Spoofed GPS time corrupts PMU phase measurements and downstream estimation. | Y24: L1 · GNSS receiver / onboard clock | Z24: L1 | AA24: L3 | AB24: =IF(OR(Z24="",AA24=""),"",IF(VALUE(MID(AA24,2,1))>VALUE(MID(Z24,2,1)),"Upward (observables)",IF(VALUE(MID(AA24,2,1))<VALUE(MID(Z24,2,1)),"Downward (config / keys / sync)","Within layer"))) -> Upward (observables) | AC24: =IF(OR(Z24="",AA24=""),"",IF(AND(MIN(VALUE(MID(Z24,2,1)),VALUE(MID(AA24,2,1)))<=1,MAX(VALUE(MID(Z24,2,1)),VALUE(MID(AA24,2,1)))>=2),"✓","")) -> ✓ | AD24: =IF(OR(Z24="",AA24=""),"",IF(AND(MIN(VALUE(MID(Z24,2,1)),VALUE(MID(AA24,2,1)))<=2,MAX(VALUE(MID(Z24,2,1)),VALUE(MID(AA24,2,1)))>=3),"✓","")) -> ✓ | AE24: =IF(OR(Z24="",AA24=""),"",IF(AND(MIN(VALUE(MID(Z24,2,1)),VALUE(MID(AA24,2,1)))<=3,MAX(VALUE(MID(Z24,2,1)),VALUE(MID(AA24,2,1)))>=4),"✓","")) | AF24: Direct | AH24: =COUNTIF('CVE Register'!$P$6:$P$300,A24) -> 0 | AI24: M01; M11; M23 | AJ24: Analogue for the cross-cutting timing dependency. | AK24: Original review set | AL24: A1.2, A1.5 | AM24: Bound threats: T1.11 | AN24: L1 > L2 > L3 > L4 (4 of 4 layers) L1: [A1.2], [A1.5], A1.4, A1.7 | L2: A2.1, A2.2, A2.4 | L3: A3.1, A3.2, A3.3, A3.4, A3.5, A3.6 | L4: A4.5, A4.6 Boundaries to first check A3.4/A3.5: 2 | to ATM A4.6: 3
