Workbook

Sheet README
A1: SATERA Extended Threat Catalogue
A2: Companion workbook to the IEEE TDSC paper: threat model of GNSS-independent LEO multilateration surveillance. Release version 1.3, 30 October 2026.
A4: Purpose | B4: Final extended catalogue of 55 threats (T1.01-T4.15). It refines the earlier asset-level SATERA catalogue of 17 entries (SC-1 to SC-17, sheet SATERA): 44 of the 55 threats refine at least one of those entries and 11 are new. Built with the methodology of the paper: STRIDE-tau for enumeration, PASTA as the process, effect-transfer graphs for propagation and PA-DREAD for ranking. Every number the paper states about the catalogue is recomputed here (sheet Checks).
A5: Sheets | B5: Catalogue: the 55 threats with scores, reach, evidence and framework mappings (filterable). Rubric: lookup tables and anchors that drive every score. Binding: threat x atlas source, with evidence level, peer-review status and verified link. Worked: Tables 4 and 5 of the paper recomputed from the Catalogue. Assets: 27-asset register with live threat counts. SATERA: the earlier 17 entries, corrected and linked to the extended threats. Checks: paper statistic vs workbook. Review: mistakes found in the earlier workbook and open items. Legends: definitions. CVE Register: the 57 CVEs of the Threat and Exploit Atlas V4, each mapped to register assets and catalogue threats (added 29 Oct 2026).
A6: How a score is made | B6: D from the goals the threat serves (and Affected users); R from the highest evidence among bound atlas entries, minus one if analogue-only; E from the adversary tier; A and Di are analyst inputs read from the attack graph (basis columns state why); S = D+R+E+A+Di; bands Low 5-9, Medium 10-14, High 15-19, Critical 20-25. Evidence, R, E, D, S and bands are formulas: change a binding, a tier or a rubric value and everything updates.
A7: Colour code | B7: Blue text = analyst input or published constant; black = formula or text. Row shading marks the layer.
A8: Status | B8: Final release. Every record (title, description, asset binding, adversary class, tier, Affected-users and Discoverability values, atlas bindings and framework mappings) was validated by a blind multi-vendor LLM panel (four models, 220 ratings; repository folder llm_panel) and then evaluated by the co-authors. The scores and the scoring algorithms were verified: sheet Checks recomputes every statistic the paper states. Column "Review status" separates the 7 baseline records, which reproduce printed values of the paper (Table 5), from the 48 extended records, which carry the same validation.
A9: Not claimed | B9: Scores are ordinal analyst derivations from the stated rubric, not probabilities. The agreement of the LLM panel on the scored fields is reported in the paper (Sec. 4.11) and in the repository folder llm_panel/results. Detection thresholds of the SATERA integrity monitor are not published, so strong/weak-pass Discoverability rests on assumptions W2 and W3. Spearman correlation and radii of the dependency graph (41 edges) are not reproduced here because the edge list is not part of this workbook.
A10: Responsible handling | B10: High-level mechanisms only: no parameters, procedures or tooling, as for the atlas.
A11: Sources | B11: Threat and Exploit Atlas (78 sources, links verified 13 Oct 2026); SATERA D6.1; Leonardi et al. 2026; SPARTA technique list and MITRE ATT&CK v20 (see Legends for what was checked).
A12: Version v1.2 (29 Oct 2026) | B12: Added: sheet CVE Register (57 CVEs from the Threat and Exploit Atlas V4, mapped to assets and threats); Catalogue columns AT to AV (related CVEs and cross-layer propagation); Assets columns M and N (CVE count and propagation per asset); five checks. Cross-layer propagation lists, for the asset a threat acts on, the layers and assets its effect can reach along the data, timing, control and hosting dependencies of the paper (assets reached only through the inferred dependencies S1 and S2 carry a dagger). Existing columns and formulas are unchanged.
A14: Quick results
A15: Threats | B15: =COUNTA(Catalogue!$A$5:$A$59) -> 55
A16: Checks passing | B16: =Checks!C118 -> 112
A17: Checks failing | B17: =Checks!C119 -> 0
A18: High or Critical (strong pass) | B18: =COUNTIF(Catalogue!$AJ$5:$AJ$59,"High")+COUNTIF(Catalogue!$AJ$5:$AJ$59,"Critical") -> 47
A19: High or Critical (weak pass) | B19: =COUNTIF(Catalogue!$AK$5:$AK$59,"High")+COUNTIF(Catalogue!$AK$5:$AK$59,"Critical") -> 47
A20: CVEs in register | B20: =COUNTA('CVE Register'!$B$5:$B$61) -> 57
A21: Threats with a related CVE | B21: =COUNTIF(Catalogue!$AT$5:$AT$59,">0") -> 12

Sheet Catalogue
A1: SATERA Extended Threat Catalogue: 55 threats, T1.01 to T4.15
A2: Built with STRIDE-tau (enumeration), PASTA (process), effect-transfer graphs and PA-DREAD (ranking) as defined in the paper, Sec. 4. Blue = analyst input; black = formula. All records were validated by a blind multi-vendor LLM panel and then evaluated by the co-authors.
A3: Identification | H3: STRIDE-tau and timing | L3: Adversary and goals | T3: Evidence (atlas) | Z3: Propagation reach | AB3: PA-DREAD (Sec. 4.8) | AL3: Basis of the scores | AO3: Cross references | AT3: CVEs and propagation (added 29 Oct 2026)
A4: ID | B4: Layer | C4: Threat | D4: Description (mechanism level) | E4: Attack vector | F4: Asset(s) | G4: Trust boundary (sits at / crosses) | H4: STRIDE-tau primary | I4: Secondary | J4: Authentication-invariance test / tau note | K4: Timing relation | L4: Adversary class | M4: Tier code | N4: Displacement | O4: Denial | P4: Deception | Q4: Disclosure | R4: Goals (n) | S4: Role | T4: Evidence | U4: Analogue only | V4: Support not peer-reviewed | W4: Bound atlas sources (#) | X4: Path evidence (#) | Y4: Mitigation IDs (from bound sources) | Z4: rho_det | AA4: rho_root | AB4: D | AC4: R | AD4: E | AE4: A | AF4: Di strong | AG4: Di weak | AH4: S strong | AI4: S weak | AJ4: Band strong | AK4: Band weak | AL4: First detection predicate / reason for Di | AM4: Affected-users basis | AN4: Displacement route | AO4: SATERA entries refined | AP4: SPARTA technique (confidence) | AQ4: ATT&CK technique (confidence) | AR4: Mapping confidence | AS4: Review status | AT4: Related CVEs (n) | AU4: Related CVEs (IDs, or products when more than four) | AV4: Cross-layer propagation (layers and assets the effect can reach)
A5: T1.01 | B5: L1 | C5: Forged ADS-B injection | D5: An emitter in the footprint broadcasts fabricated 1090ES messages for a non-existent or misidentified aircraft; the self-report carries no authentication, so reception in orbit adds no protection. | E5: Crafted 1090 MHz transmissions from a ground or airborne emitter | F5: A1.1 | G5: TB0 | H5: S | I5: T | J5: n/a: no time offset on an asset of the timing dependency | L5: AC2 | M5: T1p | P5: Y | R5: =COUNTIF(N5:Q5,"Y") -> 1 | S5: Leaf | T5: =IF(COUNTIFS(Binding!$A$5:$A$108,A5,Binding!$C$5:$C$108,"Attack")=0,"P","E"&MAXIFS(Binding!$J$5:$J$108,Binding!$A$5:$A$108,A5,Binding!$C$5:$C$108,"Attack")) -> E2 | U5: N | V5: =IF(T5="P","",IF(COUNTIFS(Binding!$A$5:$A$108,A5,Binding!$C$5:$C$108,"Attack",Binding!$J$5:$J$108,MAXIFS(Binding!$J$5:$J$108,Binding!$A$5:$A$108,A5,Binding!$C$5:$C$108,"Attack"),Binding!$H$5:$H$108,"Yes")=0,"Yes","No")) -> No | W5: #3, #59, #23, #26 | Y5: M15; M16; M17; M21 | Z5: 2 | AA5: 3 | AB5: =IF(S5="Enabler","",MAX(IF(N5="Y",Rubric!$I$5,0),IF(P5="Y",Rubric!$I$6,0),IF(O5="Y",IF(AE5>=3,Rubric!$I$7,Rubric!$I$8),0),IF(Q5="Y",Rubric!$I$9,0))) -> 4 | AC5: {=MAX(1,INDEX(Rubric!$B$5:$B$9,MATCH(T5,Rubric!$A$5:$A$9,0))-IF(AND(U5="Y",T5<>"P"),Rubric!$I$11,0))} -> 4 | AD5: {=INDEX(Rubric!$E$5:$E$9,MATCH(M5,Rubric!$D$5:$D$9,0))} -> 5 | AE5: 2 | AF5: 3 | AG5: 3 | AH5: =IF(S5="Enabler","",AB5+AC5+AD5+AE5+AF5) -> 18 | AI5: =IF(S5="Enabler","",AB5+AC5+AD5+AE5+AG5) -> 18 | AJ5: {=IF(AH5="","",INDEX(Rubric!$M$5:$M$8,MATCH(AH5,Rubric!$L$5:$L$8,1)))} -> High | AK5: {=IF(AI5="","",INDEX(Rubric!$M$5:$M$8,MATCH(AI5,Rubric!$L$5:$L$8,1)))} -> High | AL5: L3 cross-check A3.5: arrival times do not match the claimed position | AM5: several aircraft | AO5: SC-1 | AP5: EX-0014 Spoofing; IMP-0001 Deception | AQ5: T1565.002 Transmitted Data Manipulation (medium) | AR5: medium | AS5: Validated: LLM panel and co-author evaluation | AT5: =COUNTIF('CVE Register'!$X$5:$X$61,"*"&A5&"*") -> 0 | AU5: — | AV5: L1 > L2 > L3 > L4 (4 of 4 layers) L1: [A1.1], A1.3, A1.4, A1.7 | L2: A2.1, A2.2, A2.4 | L3: A3.1, A3.3, A3.4, A3.5, A3.6 | L4: A4.5, A4.6 Boundaries to first check A3.4/A3.5: 2 | to ATM A4.6: 3
A6: T1.02 | B6: L1 | C6: Replay of recorded ADS-B | D6: Genuine messages are captured and rebroadcast later or elsewhere, so that a stale or displaced position is received as current. | E6: Capture-and-rebroadcast with a software-defined radio | F6: A1.1 | G6: TB0 | H6: S | I6: T | J6: n/a: no time offset on an asset of the timing dependency | L6: AC2 | M6: T1p | P6: Y | R6: =COUNTIF(N6:Q6,"Y") -> 1 | S6: Leaf | T6: =IF(COUNTIFS(Binding!$A$5:$A$108,A6,Binding!$C$5:$C$108,"Attack")=0,"P","E"&MAXIFS(Binding!$J$5:$J$108,Binding!$A$5:$A$108,A6,Binding!$C$5:$C$108,"Attack")) -> E2 | U6: N | V6: =IF(T6="P","",IF(COUNTIFS(Binding!$A$5:$A$108,A6,Binding!$C$5:$C$108,"Attack",Binding!$J$5:$J$108,MAXIFS(Binding!$J$5:$J$108,Binding!$A$5:$A$108,A6,Binding!$C$5:$C$108,"Attack"),Binding!$H$5:$H$108,"Yes")=0,"Yes","No")) -> No | W6: #3, #59, #7 | Y6: M15; M17; M21 | Z6: 2 | AA6: 3 | AB6: =IF(S6="Enabler","",MAX(IF(N6="Y",Rubric!$I$5,0),IF(P6="Y",Rubric!$I$6,0),IF(O6="Y",IF(AE6>=3,Rubric!$I$7,Rubric!$I$8),0),IF(Q6="Y",Rubric!$I$9,0))) -> 4 | AC6: {=MAX(1,INDEX(Rubric!$B$5:$B$9,MATCH(T6,Rubric!$A$5:$A$9,0))-IF(AND(U6="Y",T6<>"P"),Rubric!$I$11,0))} -> 4 | AD6: {=INDEX(Rubric!$E$5:$E$9,MATCH(M6,Rubric!$D$5:$D$9,0))} -> 5 | AE6: 2 | AF6: 3 | AG6: 3 | AH6: =IF(S6="Enabler","",AB6+AC6+AD6+AE6+AF6) -> 18 | AI6: =IF(S6="Enabler","",AB6+AC6+AD6+AE6+AG6) -> 18 | AJ6: {=IF(AH6="","",INDEX(Rubric!$M$5:$M$8,MATCH(AH6,Rubric!$L$5:$L$8,1)))} -> High | AK6: {=IF(AI6="","",INDEX(Rubric!$M$5:$M$8,MATCH(AI6,Rubric!$L$5:$L$8,1)))} -> High | AL6: L3 cross-check A3.5: arrival times are inconsistent with the replayed position | AM6: several aircraft | AO6: SC-1 | AP6: EX-0014 Spoofing; EXF-0001 Replay (medium) | AQ6: T1565.002 Transmitted Data Manipulation (medium) | AR6: medium | AS6: Validated: LLM panel and co-author evaluation | AT6: =COUNTIF('CVE Register'!$X$5:$X$61,"*"&A6&"*") -> 0 | AU6: — | AV6: L1 > L2 > L3 > L4 (4 of 4 layers) L1: [A1.1], A1.3, A1.4, A1.7 | L2: A2.1, A2.2, A2.4 | L3: A3.1, A3.3, A3.4, A3.5, A3.6 | L4: A4.5, A4.6 Boundaries to first check A3.4/A3.5: 2 | to ATM A4.6: 3
A7: T1.03 | B7: L1 | C7: False position from the true location | D7: A deceptive or deceived aircraft (AC1) broadcasts a wrong position from its real location. Arrival times stay true, so only the E-MLAT/ADS-B cross-check can expose it; a chain that masks the discrepancy defeats the purpose of the architecture. | E7: Modified avionics or transponder input; no external emitter needed | F7: A1.1 | G7: TB0 | H7: S | I7: T | J7: n/a: no time offset on an asset of the timing dependency | K7: Derived | L7: AC1 | M7: T1c | N7: Y | P7: Y | R7: =COUNTIF(N7:Q7,"Y") -> 2 | S7: Leaf | T7: =IF(COUNTIFS(Binding!$A$5:$A$108,A7,Binding!$C$5:$C$108,"Attack")=0,"P","E"&MAXIFS(Binding!$J$5:$J$108,Binding!$A$5:$A$108,A7,Binding!$C$5:$C$108,"Attack")) -> E3 | U7: N | V7: =IF(T7="P","",IF(COUNTIFS(Binding!$A$5:$A$108,A7,Binding!$C$5:$C$108,"Attack",Binding!$J$5:$J$108,MAXIFS(Binding!$J$5:$J$108,Binding!$A$5:$A$108,A7,Binding!$C$5:$C$108,"Attack"),Binding!$H$5:$H$108,"Yes")=0,"Yes","No")) -> Yes | W7: #72, #56, #6 | Y7: M15; M18 | Z7: 2 | AA7: 3 | AB7: =IF(S7="Enabler","",MAX(IF(N7="Y",Rubric!$I$5,0),IF(P7="Y",Rubric!$I$6,0),IF(O7="Y",IF(AE7>=3,Rubric!$I$7,Rubric!$I$8),0),IF(Q7="Y",Rubric!$I$9,0))) -> 5 | AC7: {=MAX(1,INDEX(Rubric!$B$5:$B$9,MATCH(T7,Rubric!$A$5:$A$9,0))-IF(AND(U7="Y",T7<>"P"),Rubric!$I$11,0))} -> 5 | AD7: {=INDEX(Rubric!$E$5:$E$9,MATCH(M7,Rubric!$D$5:$D$9,0))} -> 4 | AE7: 1 | AF7: 3 | AG7: 3 | AH7: =IF(S7="Enabler","",AB7+AC7+AD7+AE7+AF7) -> 18 | AI7: =IF(S7="Enabler","",AB7+AC7+AD7+AE7+AG7) -> 18 | AJ7: {=IF(AH7="","",INDEX(Rubric!$M$5:$M$8,MATCH(AH7,Rubric!$L$5:$L$8,1)))} -> High | AK7: {=IF(AI7="","",INDEX(Rubric!$M$5:$M$8,MATCH(AI7,Rubric!$L$5:$L$8,1)))} -> High | AL7: L3 cross-check A3.5: mismatch between independent and broadcast position | AM7: one aircraft | AN7: Emitter and position | AO7: SC-1 | AP7: IMP-0001 Deception | AQ7: T0832 Manipulation of View (medium) | AR7: medium | AS7: Validated: LLM panel and co-author evaluation | AT7: =COUNTIF('CVE Register'!$X$5:$X$61,"*"&A7&"*") -> 0 | AU7: — | AV7: L1 > L2 > L3 > L4 (4 of 4 layers) L1: [A1.1], A1.3, A1.4, A1.7 | L2: A2.1, A2.2, A2.4 | L3: A3.1, A3.3, A3.4, A3.5, A3.6 | L4: A4.5, A4.6 Boundaries to first check A3.4/A3.5: 2 | to ATM A4.6: 3
A8: T1.04 | B8: L1 | C8: 1090 MHz jamming | D8: In-band interference raises the noise floor at the payload so that valid emissions in the footprint are not decoded. | E8: Wide- or narrow-band RF interference in the footprint | F8: A1.3 | G8: TB0 | H8: D | J8: n/a: no time offset on an asset of the timing dependency | L8: AC2 | M8: T1p | O8: Y | R8: =COUNTIF(N8:Q8,"Y") -> 1 | S8: Leaf | T8: =IF(COUNTIFS(Binding!$A$5:$A$108,A8,Binding!$C$5:$C$108,"Attack")=0,"P","E"&MAXIFS(Binding!$J$5:$J$108,Binding!$A$5:$A$108,A8,Binding!$C$5:$C$108,"Attack")) -> E2 | U8: N | V8: =IF(T8="P","",IF(COUNTIFS(Binding!$A$5:$A$108,A8,Binding!$C$5:$C$108,"Attack",Binding!$J$5:$J$108,MAXIFS(Binding!$J$5:$J$108,Binding!$A$5:$A$108,A8,Binding!$C$5:$C$108,"Attack"),Binding!$H$5:$H$108,"Yes")=0,"Yes","No")) -> No | W8: #3, #23 | Y8: M15; M16; M17; M21 | Z8: 2 | AA8: 3 | AB8: =IF(S8="Enabler","",MAX(IF(N8="Y",Rubric!$I$5,0),IF(P8="Y",Rubric!$I$6,0),IF(O8="Y",IF(AE8>=3,Rubric!$I$7,Rubric!$I$8),0),IF(Q8="Y",Rubric!$I$9,0))) -> 3 | AC8: {=MAX(1,INDEX(Rubric!$B$5:$B$9,MATCH(T8,Rubric!$A$5:$A$9,0))-IF(AND(U8="Y",T8<>"P"),Rubric!$I$11,0))} -> 4 | AD8: {=INDEX(Rubric!$E$5:$E$9,MATCH(M8,Rubric!$D$5:$D$9,0))} -> 5 | AE8: 3 | AF8: 1 | AG8: 1 | AH8: =IF(S8="Enabler","",AB8+AC8+AD8+AE8+AF8) -> 16 | AI8: =IF(S8="Enabler","",AB8+AC8+AD8+AE8+AG8) -> 16 | AJ8: {=IF(AH8="","",INDEX(Rubric!$M$5:$M$8,MATCH(AH8,Rubric!$L$5:$L$8,1)))} -> High | AK8: {=IF(AI8="","",INDEX(Rubric!$M$5:$M$8,MATCH(AI8,Rubric!$L$5:$L$8,1)))} -> High | AL8: L1/L2: loss of receptions is visible as an availability drop | AM8: one footprint | AP8: EX-0016 Jamming; IMP-0003 Denial | AQ8: T0814 Denial of Service (medium) | AR8: medium | AS8: Validated: LLM panel and co-author evaluation | AT8: =COUNTIF('CVE Register'!$X$5:$X$61,"*"&A8&"*") -> 0 | AU8: — | AV8: L1 > L2 > L3 > L4 (4 of 4 layers) L1: [A1.3], A1.4, A1.7 | L2: A2.1, A2.2, A2.4 | L3: A3.1, A3.3, A3.4, A3.5, A3.6 | L4: A4.5, A4.6 Boundaries to first check A3.4/A3.5: 2 | to ATM A4.6: 3
A9: T1.05 | B9: L1 | C9: Synchronised multi-emitter ghost target | D9: Several time-synchronised emitters in the footprint transmit so that arrival-time differences at the satellites match a false position (AC3). Whether the payload's angular resolution separates the emitters depends on pass geometry. | E9: Time-synchronised transmitters at several sites | F9: A1.1 | G9: TB0 | H9: S | I9: T | J9: Not tau: it forges emissions, not a clock offset. Timing-related because it must reproduce TDOA. | K9: Target | L9: AC3 | M9: T2 | P9: Y | R9: =COUNTIF(N9:Q9,"Y") -> 1 | S9: Leaf | T9: =IF(COUNTIFS(Binding!$A$5:$A$108,A9,Binding!$C$5:$C$108,"Attack")=0,"P","E"&MAXIFS(Binding!$J$5:$J$108,Binding!$A$5:$A$108,A9,Binding!$C$5:$C$108,"Attack")) -> E2 | U9: Y | V9: =IF(T9="P","",IF(COUNTIFS(Binding!$A$5:$A$108,A9,Binding!$C$5:$C$108,"Attack",Binding!$J$5:$J$108,MAXIFS(Binding!$J$5:$J$108,Binding!$A$5:$A$108,A9,Binding!$C$5:$C$108,"Attack"),Binding!$H$5:$H$108,"Yes")=0,"Yes","No")) -> No | W9: #5, #20, #6 | Y9: M15; M16; M17 | Z9: 2 | AA9: 3 | AB9: =IF(S9="Enabler","",MAX(IF(N9="Y",Rubric!$I$5,0),IF(P9="Y",Rubric!$I$6,0),IF(O9="Y",IF(AE9>=3,Rubric!$I$7,Rubric!$I$8),0),IF(Q9="Y",Rubric!$I$9,0))) -> 4 | AC9: {=MAX(1,INDEX(Rubric!$B$5:$B$9,MATCH(T9,Rubric!$A$5:$A$9,0))-IF(AND(U9="Y",T9<>"P"),Rubric!$I$11,0))} -> 3 | AD9: {=INDEX(Rubric!$E$5:$E$9,MATCH(M9,Rubric!$D$5:$D$9,0))} -> 3 | AE9: 2 | AF9: 3 | AG9: 5 | AH9: =IF(S9="Enabler","",AB9+AC9+AD9+AE9+AF9) -> 15 | AI9: =IF(S9="Enabler","",AB9+AC9+AD9+AE9+AG9) -> 17 | AJ9: {=IF(AH9="","",INDEX(Rubric!$M$5:$M$8,MATCH(AH9,Rubric!$L$5:$L$8,1)))} -> High | AK9: {=IF(AI9="","",INDEX(Rubric!$M$5:$M$8,MATCH(AI9,Rubric!$L$5:$L$8,1)))} -> High | AL9: Strong pass: angular resolution separates the emitters (L1/L3); weak pass: no check | AM9: several aircraft | AO9: SC-1 | AP9: EX-0014 Spoofing; IMP-0001 Deception | AQ9: T0832 Manipulation of View (medium) | AR9: medium | AS9: Validated: LLM panel and co-author evaluation | AT9: =COUNTIF('CVE Register'!$X$5:$X$61,"*"&A9&"*") -> 0 | AU9: — | AV9: L1 > L2 > L3 > L4 (4 of 4 layers) L1: [A1.1], A1.3, A1.4, A1.7 | L2: A2.1, A2.2, A2.4 | L3: A3.1, A3.3, A3.4, A3.5, A3.6 | L4: A4.5, A4.6 Boundaries to first check A3.4/A3.5: 2 | to ATM A4.6: 3
A10: T1.06 | B10: L1 | C10: Multi-emitter takeover of a real track | D10: Synchronised emitters overwrite or shadow the emission of a real aircraft so that its multilaterated position follows the attacker's, producing displacement of a genuine track. | E10: Overshadowing a genuine emission with synchronised transmitters | F10: A1.1 | G10: TB0 | H10: S | I10: T | J10: Not tau: it overwrites an emission, not a clock. Timing-related because it must reproduce TDOA. | K10: Target | L10: AC3 | M10: T2 | N10: Y | R10: =COUNTIF(N10:Q10,"Y") -> 1 | S10: Leaf | T10: =IF(COUNTIFS(Binding!$A$5:$A$108,A10,Binding!$C$5:$C$108,"Attack")=0,"P","E"&MAXIFS(Binding!$J$5:$J$108,Binding!$A$5:$A$108,A10,Binding!$C$5:$C$108,"Attack")) -> E2 | U10: Y | V10: =IF(T10="P","",IF(COUNTIFS(Binding!$A$5:$A$108,A10,Binding!$C$5:$C$108,"Attack",Binding!$J$5:$J$108,MAXIFS(Binding!$J$5:$J$108,Binding!$A$5:$A$108,A10,Binding!$C$5:$C$108,"Attack"),Binding!$H$5:$H$108,"Yes")=0,"Yes","No")) -> No | W10: #5, #20 | Y10: M15; M16; M17 | Z10: 2 | AA10: 3 | AB10: =IF(S10="Enabler","",MAX(IF(N10="Y",Rubric!$I$5,0),IF(P10="Y",Rubric!$I$6,0),IF(O10="Y",IF(AE10>=3,Rubric!$I$7,Rubric!$I$8),0),IF(Q10="Y",Rubric!$I$9,0))) -> 5 | AC10: {=MAX(1,INDEX(Rubric!$B$5:$B$9,MATCH(T10,Rubric!$A$5:$A$9,0))-IF(AND(U10="Y",T10<>"P"),Rubric!$I$11,0))} -> 3 | AD10: {=INDEX(Rubric!$E$5:$E$9,MATCH(M10,Rubric!$D$5:$D$9,0))} -> 3 | AE10: 2 | AF10: 3 | AG10: 5 | AH10: =IF(S10="Enabler","",AB10+AC10+AD10+AE10+AF10) -> 16 | AI10: =IF(S10="Enabler","",AB10+AC10+AD10+AE10+AG10) -> 18 | AJ10: {=IF(AH10="","",INDEX(Rubric!$M$5:$M$8,MATCH(AH10,Rubric!$L$5:$L$8,1)))} -> High | AK10: {=IF(AI10="","",INDEX(Rubric!$M$5:$M$8,MATCH(AI10,Rubric!$L$5:$L$8,1)))} -> High | AL10: Strong pass: separation or residual test (L3); weak pass: no check | AM10: several aircraft | AN10: Emitter and position | AO10: SC-1 | AP10: EX-0014 Spoofing; IMP-0001 Deception | AQ10: T0832 Manipulation of View (medium) | AR10: medium | AS10: Validated: LLM panel and co-author evaluation | AT10: =COUNTIF('CVE Register'!$X$5:$X$61,"*"&A10&"*") -> 0 | AU10: — | AV10: L1 > L2 > L3 > L4 (4 of 4 layers) L1: [A1.1], A1.3, A1.4, A1.7 | L2: A2.1, A2.2, A2.4 | L3: A3.1, A3.3, A3.4, A3.5, A3.6 | L4: A4.5, A4.6 Boundaries to first check A3.4/A3.5: 2 | to ATM A4.6: 3
A11: T1.07 | B11: L1 | C11: Selective suppression of emissions | D11: Targeted overshadowing or nulling removes the emissions of chosen aircraft or beams from reception while other traffic is unaffected. | E11: Directional or time-gated interference against selected targets | F11: A1.3 | G11: TB0 | H11: D | J11: n/a: no time offset on an asset of the timing dependency | L11: AC2 | M11: T1c | O11: Y | R11: =COUNTIF(N11:Q11,"Y") -> 1 | S11: Leaf | T11: =IF(COUNTIFS(Binding!$A$5:$A$108,A11,Binding!$C$5:$C$108,"Attack")=0,"P","E"&MAXIFS(Binding!$J$5:$J$108,Binding!$A$5:$A$108,A11,Binding!$C$5:$C$108,"Attack")) -> E2 | U11: N | V11: =IF(T11="P","",IF(COUNTIFS(Binding!$A$5:$A$108,A11,Binding!$C$5:$C$108,"Attack",Binding!$J$5:$J$108,MAXIFS(Binding!$J$5:$J$108,Binding!$A$5:$A$108,A11,Binding!$C$5:$C$108,"Attack"),Binding!$H$5:$H$108,"Yes")=0,"Yes","No")) -> No | W11: #3, #44 | Y11: M15; M17; M21 | Z11: 2 | AA11: 3 | AB11: =IF(S11="Enabler","",MAX(IF(N11="Y",Rubric!$I$5,0),IF(P11="Y",Rubric!$I$6,0),IF(O11="Y",IF(AE11>=3,Rubric!$I$7,Rubric!$I$8),0),IF(Q11="Y",Rubric!$I$9,0))) -> 2 | AC11: {=MAX(1,INDEX(Rubric!$B$5:$B$9,MATCH(T11,Rubric!$A$5:$A$9,0))-IF(AND(U11="Y",T11<>"P"),Rubric!$I$11,0))} -> 4 | AD11: {=INDEX(Rubric!$E$5:$E$9,MATCH(M11,Rubric!$D$5:$D$9,0))} -> 4 | AE11: 2 | AF11: 2 | AG11: 2 | AH11: =IF(S11="Enabler","",AB11+AC11+AD11+AE11+AF11) -> 14 | AI11: =IF(S11="Enabler","",AB11+AC11+AD11+AE11+AG11) -> 14 | AJ11: {=IF(AH11="","",INDEX(Rubric!$M$5:$M$8,MATCH(AH11,Rubric!$L$5:$L$8,1)))} -> Medium | AK11: {=IF(AI11="","",INDEX(Rubric!$M$5:$M$8,MATCH(AI11,Rubric!$L$5:$L$8,1)))} -> Medium | AL11: L2: reports for the target are missing, noticed as a coverage gap | AM11: several aircraft | AP11: EX-0016 Jamming; DE-0002.02 Jam Link Signal (medium) | AQ11: T0814 Denial of Service (medium) | AR11: medium | AS11: Validated: LLM panel and co-author evaluation | AT11: =COUNTIF('CVE Register'!$X$5:$X$61,"*"&A11&"*") -> 0 | AU11: — | AV11: L1 > L2 > L3 > L4 (4 of 4 layers) L1: [A1.3], A1.4, A1.7 | L2: A2.1, A2.2, A2.4 | L3: A3.1, A3.3, A3.4, A3.5, A3.6 | L4: A4.5, A4.6 Boundaries to first check A3.4/A3.5: 2 | to ATM A4.6: 3
A12: T1.08 | B12: L1 | C12: Message flooding of the payload | D12: Large volumes of valid-looking or garbled 1090 MHz squitters saturate the receive and decode chain, so genuine messages are lost. | E12: High-rate message generation by one or more emitters | F12: A1.1 | G12: TB0 | H12: D | J12: n/a: no time offset on an asset of the timing dependency | L12: AC2 | M12: T1c | O12: Y | R12: =COUNTIF(N12:Q12,"Y") -> 1 | S12: Leaf | T12: =IF(COUNTIFS(Binding!$A$5:$A$108,A12,Binding!$C$5:$C$108,"Attack")=0,"P","E"&MAXIFS(Binding!$J$5:$J$108,Binding!$A$5:$A$108,A12,Binding!$C$5:$C$108,"Attack")) -> E1 | U12: Y | V12: =IF(T12="P","",IF(COUNTIFS(Binding!$A$5:$A$108,A12,Binding!$C$5:$C$108,"Attack",Binding!$J$5:$J$108,MAXIFS(Binding!$J$5:$J$108,Binding!$A$5:$A$108,A12,Binding!$C$5:$C$108,"Attack"),Binding!$H$5:$H$108,"Yes")=0,"Yes","No")) -> No | W12: #13, #16 | Y12: M09; M25 | Z12: 2 | AA12: 3 | AB12: =IF(S12="Enabler","",MAX(IF(N12="Y",Rubric!$I$5,0),IF(P12="Y",Rubric!$I$6,0),IF(O12="Y",IF(AE12>=3,Rubric!$I$7,Rubric!$I$8),0),IF(Q12="Y",Rubric!$I$9,0))) -> 3 | AC12: {=MAX(1,INDEX(Rubric!$B$5:$B$9,MATCH(T12,Rubric!$A$5:$A$9,0))-IF(AND(U12="Y",T12<>"P"),Rubric!$I$11,0))} -> 2 | AD12: {=INDEX(Rubric!$E$5:$E$9,MATCH(M12,Rubric!$D$5:$D$9,0))} -> 4 | AE12: 3 | AF12: 1 | AG12: 1 | AH12: =IF(S12="Enabler","",AB12+AC12+AD12+AE12+AF12) -> 13 | AI12: =IF(S12="Enabler","",AB12+AC12+AD12+AE12+AG12) -> 13 | AJ12: {=IF(AH12="","",INDEX(Rubric!$M$5:$M$8,MATCH(AH12,Rubric!$L$5:$L$8,1)))} -> Medium | AK12: {=IF(AI12="","",INDEX(Rubric!$M$5:$M$8,MATCH(AI12,Rubric!$L$5:$L$8,1)))} -> Medium | AL12: L1: saturation is observable in receiver statistics | AM12: one footprint | AP12: EX-0013 Flooding; EX-0013.02 Erroneous Input (high) | AQ12: T1499 Endpoint Denial of Service (medium) | AR12: medium | AS12: Validated: LLM panel and co-author evaluation | AT12: =COUNTIF('CVE Register'!$X$5:$X$61,"*"&A12&"*") -> 0 | AU12: — | AV12: L1 > L2 > L3 > L4 (4 of 4 layers) L1: [A1.1], A1.3, A1.4, A1.7 | L2: A2.1, A2.2, A2.4 | L3: A3.1, A3.3, A3.4, A3.5, A3.6 | L4: A4.5, A4.6 Boundaries to first check A3.4/A3.5: 2 | to ATM A4.6: 3
A13: T1.09 | B13: L1 | C13: Biased observables at reception | D13: Interference or crafted signal structure shifts the measured TOA, FOA or AOA of a genuine emission at the payload, so the observable is biased before it is stamped. | E13: Crafted RF injection, frequency offset, multipath or array spoofing | F13: A1.4 | G13: TB1 | H13: T | I13: S | J13: n/a: no time offset on an asset of the timing dependency | L13: AC3 | M13: T2 | N13: Y | R13: =COUNTIF(N13:Q13,"Y") -> 1 | S13: Leaf | T13: =IF(COUNTIFS(Binding!$A$5:$A$108,A13,Binding!$C$5:$C$108,"Attack")=0,"P","E"&MAXIFS(Binding!$J$5:$J$108,Binding!$A$5:$A$108,A13,Binding!$C$5:$C$108,"Attack")) -> E1 | U13: Y | V13: =IF(T13="P","",IF(COUNTIFS(Binding!$A$5:$A$108,A13,Binding!$C$5:$C$108,"Attack",Binding!$J$5:$J$108,MAXIFS(Binding!$J$5:$J$108,Binding!$A$5:$A$108,A13,Binding!$C$5:$C$108,"Attack"),Binding!$H$5:$H$108,"Yes")=0,"Yes","No")) -> No | W13: #8, #9, #6 | Y13: M15; M16 | Z13: 2 | AA13: 3 | AB13: =IF(S13="Enabler","",MAX(IF(N13="Y",Rubric!$I$5,0),IF(P13="Y",Rubric!$I$6,0),IF(O13="Y",IF(AE13>=3,Rubric!$I$7,Rubric!$I$8),0),IF(Q13="Y",Rubric!$I$9,0))) -> 5 | AC13: {=MAX(1,INDEX(Rubric!$B$5:$B$9,MATCH(T13,Rubric!$A$5:$A$9,0))-IF(AND(U13="Y",T13<>"P"),Rubric!$I$11,0))} -> 2 | AD13: {=INDEX(Rubric!$E$5:$E$9,MATCH(M13,Rubric!$D$5:$D$9,0))} -> 3 | AE13: 3 | AF13: 3 | AG13: 5 | AH13: =IF(S13="Enabler","",AB13+AC13+AD13+AE13+AF13) -> 16 | AI13: =IF(S13="Enabler","",AB13+AC13+AD13+AE13+AG13) -> 18 | AJ13: {=IF(AH13="","",INDEX(Rubric!$M$5:$M$8,MATCH(AH13,Rubric!$L$5:$L$8,1)))} -> High | AK13: {=IF(AI13="","",INDEX(Rubric!$M$5:$M$8,MATCH(AI13,Rubric!$L$5:$L$8,1)))} -> High | AL13: Strong pass: residual test A3.4 (L3); weak pass: bias inside the stealth window | AM13: one footprint | AN13: Observables | AO13: SC-2 | AP13: EX-0014.03 Spoofing: Sensor Data (medium) | AQ13: T1565.003 Runtime Data Manipulation (medium) | AR13: medium | AS13: Validated: LLM panel and co-author evaluation | AT13: =COUNTIF('CVE Register'!$X$5:$X$61,"*"&A13&"*") -> 0 | AU13: — | AV13: L1 > L2 > L3 > L4 (4 of 4 layers) L1: [A1.4], A1.7 | L2: A2.1, A2.2, A2.4 | L3: A3.1, A3.3, A3.4, A3.5, A3.6 | L4: A4.5, A4.6 Boundaries to first check A3.4/A3.5: 2 | to ATM A4.6: 3
A14: T1.10 | B14: L1 | C14: GNSS jamming of the onboard timing receiver | D14: Ground-based interference denies the GNSS input that disciplines the onboard clock, forcing holdover and degrading time quality. The primary effect is loss of an input; any drift is a secondary tau effect. | E14: Ground jammer pointed at the satellite's GNSS receiver | F14: A1.2, A1.5 | G14: TB0, TB1 | H14: D | I14: tau | J14: Primary D: the effect is loss of the GNSS input. Any holdover drift is recorded as a secondary tau effect. | K14: Target | L14: AC4 | M14: T2 | N14: Y | O14: Y | R14: =COUNTIF(N14:Q14,"Y") -> 2 | S14: Leaf | T14: =IF(COUNTIFS(Binding!$A$5:$A$108,A14,Binding!$C$5:$C$108,"Attack")=0,"P","E"&MAXIFS(Binding!$J$5:$J$108,Binding!$A$5:$A$108,A14,Binding!$C$5:$C$108,"Attack")) -> E3 | U14: Y | V14: =IF(T14="P","",IF(COUNTIFS(Binding!$A$5:$A$108,A14,Binding!$C$5:$C$108,"Attack",Binding!$J$5:$J$108,MAXIFS(Binding!$J$5:$J$108,Binding!$A$5:$A$108,A14,Binding!$C$5:$C$108,"Attack"),Binding!$H$5:$H$108,"Yes")=0,"Yes","No")) -> No | W14: #54, #75, #69, #70, #22, #25 | Y14: M01; M12; M14; M18; M19; M23 | Z14: 2 | AA14: 3 | AB14: =IF(S14="Enabler","",MAX(IF(N14="Y",Rubric!$I$5,0),IF(P14="Y",Rubric!$I$6,0),IF(O14="Y",IF(AE14>=3,Rubric!$I$7,Rubric!$I$8),0),IF(Q14="Y",Rubric!$I$9,0))) -> 5 | AC14: {=MAX(1,INDEX(Rubric!$B$5:$B$9,MATCH(T14,Rubric!$A$5:$A$9,0))-IF(AND(U14="Y",T14<>"P"),Rubric!$I$11,0))} -> 4 | AD14: {=INDEX(Rubric!$E$5:$E$9,MATCH(M14,Rubric!$D$5:$D$9,0))} -> 3 | AE14: 4 | AF14: 1 | AG14: 1 | AH14: =IF(S14="Enabler","",AB14+AC14+AD14+AE14+AF14) -> 17 | AI14: =IF(S14="Enabler","",AB14+AC14+AD14+AE14+AG14) -> 17 | AJ14: {=IF(AH14="","",INDEX(Rubric!$M$5:$M$8,MATCH(AH14,Rubric!$L$5:$L$8,1)))} -> High | AK14: {=IF(AI14="","",INDEX(Rubric!$M$5:$M$8,MATCH(AI14,Rubric!$L$5:$L$8,1)))} -> High | AL14: L1: the clock checks flag loss of lock | AM14: several footprints | AN14: Clock | AO14: SC-5 | AP14: EX-0016.03 Jamming: Position, Navigation, and Timing (high) | AQ14: (unmapped) | AR14: high | AS14: Validated: LLM panel and co-author evaluation | AT14: =COUNTIF('CVE Register'!$X$5:$X$61,"*"&A14&"*") -> 1 | AU14: CVE-2026-3893 | AV14: L1 > L2 > L3 > L4 (4 of 4 layers) L1: [A1.2], [A1.5], A1.4, A1.7 | L2: A2.1, A2.2, A2.4 | L3: A3.1, A3.2, A3.3, A3.4, A3.5, A3.6 | L4: A4.5, A4.6 Boundaries to first check A3.4/A3.5: 2 | to ATM A4.6: 3
A15: T1.11 | B15: L1 | C15: GNSS spoofing of the onboard clock | D15: Counterfeit GNSS signals pull the GNSS-disciplined onboard clock, biasing every observable it stamps. Every report stays authentic and wrong; a covert 100 ns step is the hardest case. | E15: Counterfeit GNSS signals with a tracking, directional transmitter | F15: A1.2, A1.5 | G15: TB0, TB1 | H15: tau | I15: S | J15: Authentication-invariance test: with every message authenticated (A3), the spoofed input still offsets the clock, so primary tau, secondary Spoofing. | K15: Target | L15: AC4 | M15: T3 | N15: Y | R15: =COUNTIF(N15:Q15,"Y") -> 1 | S15: Leaf | T15: =IF(COUNTIFS(Binding!$A$5:$A$108,A15,Binding!$C$5:$C$108,"Attack")=0,"P","E"&MAXIFS(Binding!$J$5:$J$108,Binding!$A$5:$A$108,A15,Binding!$C$5:$C$108,"Attack")) -> E2 | U15: Y | V15: =IF(T15="P","",IF(COUNTIFS(Binding!$A$5:$A$108,A15,Binding!$C$5:$C$108,"Attack",Binding!$J$5:$J$108,MAXIFS(Binding!$J$5:$J$108,Binding!$A$5:$A$108,A15,Binding!$C$5:$C$108,"Attack"),Binding!$H$5:$H$108,"Yes")=0,"Yes","No")) -> No | W15: #4, #47, #57, #19, #53 | X15: #76 | Y15: M01; M11; M12; M18; M19; M23 | Z15: 2 | AA15: 3 | AB15: =IF(S15="Enabler","",MAX(IF(N15="Y",Rubric!$I$5,0),IF(P15="Y",Rubric!$I$6,0),IF(O15="Y",IF(AE15>=3,Rubric!$I$7,Rubric!$I$8),0),IF(Q15="Y",Rubric!$I$9,0))) -> 5 | AC15: {=MAX(1,INDEX(Rubric!$B$5:$B$9,MATCH(T15,Rubric!$A$5:$A$9,0))-IF(AND(U15="Y",T15<>"P"),Rubric!$I$11,0))} -> 3 | AD15: {=INDEX(Rubric!$E$5:$E$9,MATCH(M15,Rubric!$D$5:$D$9,0))} -> 2 | AE15: 3 | AF15: 3 | AG15: 5 | AH15: =IF(S15="Enabler","",AB15+AC15+AD15+AE15+AF15) -> 16 | AI15: =IF(S15="Enabler","",AB15+AC15+AD15+AE15+AG15) -> 18 | AJ15: {=IF(AH15="","",INDEX(Rubric!$M$5:$M$8,MATCH(AH15,Rubric!$L$5:$L$8,1)))} -> High | AK15: {=IF(AI15="","",INDEX(Rubric!$M$5:$M$8,MATCH(AI15,Rubric!$L$5:$L$8,1)))} -> High | AL15: Strong pass: L3 residual test; weak pass: bias inside the stealth window | AM15: one footprint | AN15: Clock | AO15: SC-3; SC-5 | AP15: EX-0014.04 Spoofing: PNT; EX-0014.01 Spoofing: Time Spoof (high) | AQ15: (unmapped) | AR15: high | AS15: Baseline: reproduces Table 5 of the paper | AT15: =COUNTIF('CVE Register'!$X$5:$X$61,"*"&A15&"*") -> 1 | AU15: CVE-2026-3893 | AV15: L1 > L2 > L3 > L4 (4 of 4 layers) L1: [A1.2], [A1.5], A1.4, A1.7 | L2: A2.1, A2.2, A2.4 | L3: A3.1, A3.2, A3.3, A3.4, A3.5, A3.6 | L4: A4.5, A4.6 Boundaries to first check A3.4/A3.5: 2 | to ATM A4.6: 3
A16: T1.12 | B16: L1 | C16: Weakly authenticated telecommand acceptance | D16: The satellite accepts commands that lack effective link-layer authentication or replay protection, allowing unauthorised commanding of the bus and payload. Hosted-asset edges A1.6 to A1.4 and A1.5 are an inferred reading (S1). | E16: Command uplink without effective authentication | F16: A1.6 | G16: TB1 | H16: E | I16: S | J16: n/a: no time offset on an asset of the timing dependency | L16: AC6 | M16: T2 | N16: Y | O16: Y | R16: =COUNTIF(N16:Q16,"Y") -> 2 | S16: Leaf | T16: =IF(COUNTIFS(Binding!$A$5:$A$108,A16,Binding!$C$5:$C$108,"Attack")=0,"P","E"&MAXIFS(Binding!$J$5:$J$108,Binding!$A$5:$A$108,A16,Binding!$C$5:$C$108,"Attack")) -> E2 | U16: N | V16: =IF(T16="P","",IF(COUNTIFS(Binding!$A$5:$A$108,A16,Binding!$C$5:$C$108,"Attack",Binding!$J$5:$J$108,MAXIFS(Binding!$J$5:$J$108,Binding!$A$5:$A$108,A16,Binding!$C$5:$C$108,"Attack"),Binding!$H$5:$H$108,"Yes")=0,"Yes","No")) -> Yes | W16: #67, #15, #60 | Y16: M04; M06; M22; M24 | Z16: 2 | AA16: 3 | AB16: =IF(S16="Enabler","",MAX(IF(N16="Y",Rubric!$I$5,0),IF(P16="Y",Rubric!$I$6,0),IF(O16="Y",IF(AE16>=3,Rubric!$I$7,Rubric!$I$8),0),IF(Q16="Y",Rubric!$I$9,0))) -> 5 | AC16: {=MAX(1,INDEX(Rubric!$B$5:$B$9,MATCH(T16,Rubric!$A$5:$A$9,0))-IF(AND(U16="Y",T16<>"P"),Rubric!$I$11,0))} -> 4 | AD16: {=INDEX(Rubric!$E$5:$E$9,MATCH(M16,Rubric!$D$5:$D$9,0))} -> 3 | AE16: 4 | AF16: 4 | AG16: 4 | AH16: =IF(S16="Enabler","",AB16+AC16+AD16+AE16+AF16) -> 20 | AI16: =IF(S16="Enabler","",AB16+AC16+AD16+AE16+AG16) -> 20 | AJ16: {=IF(AH16="","",INDEX(Rubric!$M$5:$M$8,MATCH(AH16,Rubric!$L$5:$L$8,1)))} -> Critical | AK16: {=IF(AI16="","",INDEX(Rubric!$M$5:$M$8,MATCH(AI16,Rubric!$L$5:$L$8,1)))} -> Critical | AL16: L4 only: anomalous commands are found through telemetry audit | AM16: several footprints | AN16: Platform and command | AO16: SC-4; SC-15 | AP16: EX-0001 Replay (command packets); IA-0007.02 Malicious Commanding via Valid GS (medium) | AQ16: (unmapped) | AR16: medium | AS16: Validated: LLM panel and co-author evaluation | AT16: =COUNTIF('CVE Register'!$X$5:$X$61,"*"&A16&"*") -> 0 | AU16: — | AV16: L1 > L2 > L3 > L4 (4 of 4 layers) L1: [A1.6], A1.4†, A1.5†, A1.7† | L2: A2.1†, A2.2†, A2.4† | L3: A3.1†, A3.2†, A3.3†, A3.4†, A3.5†, A3.6† | L4: A4.5†, A4.6† Boundaries to first check A3.4/A3.5: 2 | to ATM A4.6: 3
A17: T1.13 | B17: L1 | C17: Flight-software memory-safety defect exploitation | D17: A defect in flight or bus software is exploited to gain control of the bus, the payload processor or the clock. | E17: Exploitable software defect reachable from the command path | F17: A1.6 | G17: TB1 | H17: E | I17: T | J17: n/a: no time offset on an asset of the timing dependency | L17: AC6 | M17: T2 | N17: Y | O17: Y | R17: =COUNTIF(N17:Q17,"Y") -> 2 | S17: Leaf | T17: =IF(COUNTIFS(Binding!$A$5:$A$108,A17,Binding!$C$5:$C$108,"Attack")=0,"P","E"&MAXIFS(Binding!$J$5:$J$108,Binding!$A$5:$A$108,A17,Binding!$C$5:$C$108,"Attack")) -> E2 | U17: Y | V17: =IF(T17="P","",IF(COUNTIFS(Binding!$A$5:$A$108,A17,Binding!$C$5:$C$108,"Attack",Binding!$J$5:$J$108,MAXIFS(Binding!$J$5:$J$108,Binding!$A$5:$A$108,A17,Binding!$C$5:$C$108,"Attack"),Binding!$H$5:$H$108,"Yes")=0,"Yes","No")) -> Yes | W17: #65, #15 | Y17: M04; M05; M10; M13; M24 | Z17: 2 | AA17: 3 | AB17: =IF(S17="Enabler","",MAX(IF(N17="Y",Rubric!$I$5,0),IF(P17="Y",Rubric!$I$6,0),IF(O17="Y",IF(AE17>=3,Rubric!$I$7,Rubric!$I$8),0),IF(Q17="Y",Rubric!$I$9,0))) -> 5 | AC17: {=MAX(1,INDEX(Rubric!$B$5:$B$9,MATCH(T17,Rubric!$A$5:$A$9,0))-IF(AND(U17="Y",T17<>"P"),Rubric!$I$11,0))} -> 3 | AD17: {=INDEX(Rubric!$E$5:$E$9,MATCH(M17,Rubric!$D$5:$D$9,0))} -> 3 | AE17: 4 | AF17: 4 | AG17: 4 | AH17: =IF(S17="Enabler","",AB17+AC17+AD17+AE17+AF17) -> 19 | AI17: =IF(S17="Enabler","",AB17+AC17+AD17+AE17+AG17) -> 19 | AJ17: {=IF(AH17="","",INDEX(Rubric!$M$5:$M$8,MATCH(AH17,Rubric!$L$5:$L$8,1)))} -> High | AK17: {=IF(AI17="","",INDEX(Rubric!$M$5:$M$8,MATCH(AI17,Rubric!$L$5:$L$8,1)))} -> High | AL17: L4 only: compromise is found through telemetry audit | AM17: several footprints | AN17: Platform and command | AO17: SC-4 | AP17: EX-0009.01 Exploit Code Flaws: Flight Software (high) | AQ17: T0890 Exploitation for Privilege Escalation (medium) | AR17: medium | AS17: Validated: LLM panel and co-author evaluation | AT17: =COUNTIF('CVE Register'!$X$5:$X$61,"*"&A17&"*") -> 5 | AU17: 5 CVEs: NASA cFS Aquila (4), NASA F Prime (1) | AV17: L1 > L2 > L3 > L4 (4 of 4 layers) L1: [A1.6], A1.4†, A1.5†, A1.7† | L2: A2.1†, A2.2†, A2.4† | L3: A3.1†, A3.2†, A3.3†, A3.4†, A3.5†, A3.6† | L4: A4.5†, A4.6† Boundaries to first check A3.4/A3.5: 2 | to ATM A4.6: 3
A18: T1.14 | B18: L1 | C18: Firmware compromise or secure-boot bypass | D18: Payload or bus firmware is altered, or its boot chain bypassed, giving persistent control or latent behaviour. | E18: Fault injection or an unauthenticated update path | F18: A1.6 | G18: TB1 | H18: E | I18: T | J18: n/a: no time offset on an asset of the timing dependency | L18: AC6 | M18: T3 | N18: Y | O18: Y | R18: =COUNTIF(N18:Q18,"Y") -> 2 | S18: Leaf | T18: =IF(COUNTIFS(Binding!$A$5:$A$108,A18,Binding!$C$5:$C$108,"Attack")=0,"P","E"&MAXIFS(Binding!$J$5:$J$108,Binding!$A$5:$A$108,A18,Binding!$C$5:$C$108,"Attack")) -> E2 | U18: Y | V18: =IF(T18="P","",IF(COUNTIFS(Binding!$A$5:$A$108,A18,Binding!$C$5:$C$108,"Attack",Binding!$J$5:$J$108,MAXIFS(Binding!$J$5:$J$108,Binding!$A$5:$A$108,A18,Binding!$C$5:$C$108,"Attack"),Binding!$H$5:$H$108,"Yes")=0,"Yes","No")) -> Yes | W18: #64, #15 | Y18: M04; M24 | Z18: 2 | AA18: 3 | AB18: =IF(S18="Enabler","",MAX(IF(N18="Y",Rubric!$I$5,0),IF(P18="Y",Rubric!$I$6,0),IF(O18="Y",IF(AE18>=3,Rubric!$I$7,Rubric!$I$8),0),IF(Q18="Y",Rubric!$I$9,0))) -> 5 | AC18: {=MAX(1,INDEX(Rubric!$B$5:$B$9,MATCH(T18,Rubric!$A$5:$A$9,0))-IF(AND(U18="Y",T18<>"P"),Rubric!$I$11,0))} -> 3 | AD18: {=INDEX(Rubric!$E$5:$E$9,MATCH(M18,Rubric!$D$5:$D$9,0))} -> 2 | AE18: 5 | AF18: 4 | AG18: 4 | AH18: =IF(S18="Enabler","",AB18+AC18+AD18+AE18+AF18) -> 19 | AI18: =IF(S18="Enabler","",AB18+AC18+AD18+AE18+AG18) -> 19 | AJ18: {=IF(AH18="","",INDEX(Rubric!$M$5:$M$8,MATCH(AH18,Rubric!$L$5:$L$8,1)))} -> High | AK18: {=IF(AI18="","",INDEX(Rubric!$M$5:$M$8,MATCH(AI18,Rubric!$L$5:$L$8,1)))} -> High | AL18: L4 only: persistent changes are found through baseline comparison | AM18: whole constellation | AN18: Platform and command | AO18: SC-4 | AP18: EX-0005.01 Exploit Hardware/Firmware Corruption: Design Flaws; EX-0004 Compromise Boot Memory (high) | AQ18: (unmapped) | AR18: medium | AS18: Validated: LLM panel and co-author evaluation | AT18: =COUNTIF('CVE Register'!$X$5:$X$61,"*"&A18&"*") -> 0 | AU18: — | AV18: L1 > L2 > L3 > L4 (4 of 4 layers) L1: [A1.6], A1.4†, A1.5†, A1.7† | L2: A2.1†, A2.2†, A2.4† | L3: A3.1†, A3.2†, A3.3†, A3.4†, A3.5†, A3.6† | L4: A4.5†, A4.6† Boundaries to first check A3.4/A3.5: 2 | to ATM A4.6: 3
A19: T1.15 | B19: L1 | C19: Ground-station terminal compromise | D19: Remote compromise of ground-station modems or terminals (default credentials, exposed management) is used to disrupt reception or the command link. | E19: Internet-exposed management interfaces and hard-coded credentials | F19: A1.7 | G19: TB2 | H19: D | I19: E | J19: n/a: no time offset on an asset of the timing dependency | L19: AC6 | M19: T2 | O19: Y | R19: =COUNTIF(N19:Q19,"Y") -> 1 | S19: Leaf | T19: =IF(COUNTIFS(Binding!$A$5:$A$108,A19,Binding!$C$5:$C$108,"Attack")=0,"P","E"&MAXIFS(Binding!$J$5:$J$108,Binding!$A$5:$A$108,A19,Binding!$C$5:$C$108,"Attack")) -> E3 | U19: Y | V19: =IF(T19="P","",IF(COUNTIFS(Binding!$A$5:$A$108,A19,Binding!$C$5:$C$108,"Attack",Binding!$J$5:$J$108,MAXIFS(Binding!$J$5:$J$108,Binding!$A$5:$A$108,A19,Binding!$C$5:$C$108,"Attack"),Binding!$H$5:$H$108,"Yes")=0,"Yes","No")) -> Yes | W19: #62, #61 | Y19: M06; M13; M24 | Z19: 2 | AA19: 3 | AB19: =IF(S19="Enabler","",MAX(IF(N19="Y",Rubric!$I$5,0),IF(P19="Y",Rubric!$I$6,0),IF(O19="Y",IF(AE19>=3,Rubric!$I$7,Rubric!$I$8),0),IF(Q19="Y",Rubric!$I$9,0))) -> 3 | AC19: {=MAX(1,INDEX(Rubric!$B$5:$B$9,MATCH(T19,Rubric!$A$5:$A$9,0))-IF(AND(U19="Y",T19<>"P"),Rubric!$I$11,0))} -> 4 | AD19: {=INDEX(Rubric!$E$5:$E$9,MATCH(M19,Rubric!$D$5:$D$9,0))} -> 3 | AE19: 4 | AF19: 4 | AG19: 4 | AH19: =IF(S19="Enabler","",AB19+AC19+AD19+AE19+AF19) -> 18 | AI19: =IF(S19="Enabler","",AB19+AC19+AD19+AE19+AG19) -> 18 | AJ19: {=IF(AH19="","",INDEX(Rubric!$M$5:$M$8,MATCH(AH19,Rubric!$L$5:$L$8,1)))} -> High | AK19: {=IF(AI19="","",INDEX(Rubric!$M$5:$M$8,MATCH(AI19,Rubric!$L$5:$L$8,1)))} -> High | AL19: L4 only: found by operations monitoring | AM19: several footprints | AP19: IA-0007 Compromise Ground System (high) | AQ19: T0866 Exploitation of Remote Services (medium) | AR19: medium | AS19: Validated: LLM panel and co-author evaluation | AT19: =COUNTIF('CVE Register'!$X$5:$X$61,"*"&A19&"*") -> 3 | AU19: CVE-2014-2941, CVE-2014-2942, CVE-2014-2964 | AV19: L1 > L3 > L4 (3 of 4 layers) L1: [A1.7] | L3: A3.1, A3.3, A3.4, A3.5, A3.6 | L4: A4.5, A4.6 Boundaries to first check A3.4/A3.5: 2 | to ATM A4.6: 3
A20: T1.16 | B20: L1 | C20: Ground-station reception denial | D20: RF interference or overload of the ground-station antennas and modems blocks the downlink or the telecommand path. | E20: RF interference or resource exhaustion at the ground station | F20: A1.7 | G20: TB2 | H20: D | J20: n/a: no time offset on an asset of the timing dependency | L20: AC5 | M20: T2 | O20: Y | R20: =COUNTIF(N20:Q20,"Y") -> 1 | S20: Leaf | T20: =IF(COUNTIFS(Binding!$A$5:$A$108,A20,Binding!$C$5:$C$108,"Attack")=0,"P","E"&MAXIFS(Binding!$J$5:$J$108,Binding!$A$5:$A$108,A20,Binding!$C$5:$C$108,"Attack")) -> E1 | U20: Y | V20: =IF(T20="P","",IF(COUNTIFS(Binding!$A$5:$A$108,A20,Binding!$C$5:$C$108,"Attack",Binding!$J$5:$J$108,MAXIFS(Binding!$J$5:$J$108,Binding!$A$5:$A$108,A20,Binding!$C$5:$C$108,"Attack"),Binding!$H$5:$H$108,"Yes")=0,"Yes","No")) -> No | W20: #21, #13 | Y20: M09; M25 | Z20: 2 | AA20: 3 | AB20: =IF(S20="Enabler","",MAX(IF(N20="Y",Rubric!$I$5,0),IF(P20="Y",Rubric!$I$6,0),IF(O20="Y",IF(AE20>=3,Rubric!$I$7,Rubric!$I$8),0),IF(Q20="Y",Rubric!$I$9,0))) -> 3 | AC20: {=MAX(1,INDEX(Rubric!$B$5:$B$9,MATCH(T20,Rubric!$A$5:$A$9,0))-IF(AND(U20="Y",T20<>"P"),Rubric!$I$11,0))} -> 2 | AD20: {=INDEX(Rubric!$E$5:$E$9,MATCH(M20,Rubric!$D$5:$D$9,0))} -> 3 | AE20: 3 | AF20: 2 | AG20: 2 | AH20: =IF(S20="Enabler","",AB20+AC20+AD20+AE20+AF20) -> 13 | AI20: =IF(S20="Enabler","",AB20+AC20+AD20+AE20+AG20) -> 13 | AJ20: {=IF(AH20="","",INDEX(Rubric!$M$5:$M$8,MATCH(AH20,Rubric!$L$5:$L$8,1)))} -> Medium | AK20: {=IF(AI20="","",INDEX(Rubric!$M$5:$M$8,MATCH(AI20,Rubric!$L$5:$L$8,1)))} -> Medium | AL20: L2: missing downlink data is noticed immediately | AM20: one footprint | AP20: EX-0016.02 Jamming: Downlink Jamming (high) | AQ20: T0814 Denial of Service (medium) | AR20: medium | AS20: Validated: LLM panel and co-author evaluation | AT20: =COUNTIF('CVE Register'!$X$5:$X$61,"*"&A20&"*") -> 0 | AU20: — | AV20: L1 > L3 > L4 (3 of 4 layers) L1: [A1.7] | L3: A3.1, A3.3, A3.4, A3.5, A3.6 | L4: A4.5, A4.6 Boundaries to first check A3.4/A3.5: 2 | to ATM A4.6: 3
A21: T2.01 | B21: L2 | C21: Modified TOA/FOA/AOA values in reports | D21: Observable fields of reports in transit are altered, biasing the multilateration input while each message stays well-formed. Specific to multilateration. Under W4 nothing at L2 detects it. | E21: Alteration of report fields on the relay path | F21: A2.1 | G21: TB2 | H21: T | J21: n/a: no time offset on an asset of the timing dependency | K21: Derived | L21: AC5 | M21: T2 | N21: Y | R21: =COUNTIF(N21:Q21,"Y") -> 1 | S21: Leaf | T21: =IF(COUNTIFS(Binding!$A$5:$A$108,A21,Binding!$C$5:$C$108,"Attack")=0,"P","E"&MAXIFS(Binding!$J$5:$J$108,Binding!$A$5:$A$108,A21,Binding!$C$5:$C$108,"Attack")) -> E1 | U21: Y | V21: =IF(T21="P","",IF(COUNTIFS(Binding!$A$5:$A$108,A21,Binding!$C$5:$C$108,"Attack",Binding!$J$5:$J$108,MAXIFS(Binding!$J$5:$J$108,Binding!$A$5:$A$108,A21,Binding!$C$5:$C$108,"Attack"),Binding!$H$5:$H$108,"Yes")=0,"Yes","No")) -> No | W21: #17, #18, #39 | Y21: M20 | Z21: 1 | AA21: 2 | AB21: =IF(S21="Enabler","",MAX(IF(N21="Y",Rubric!$I$5,0),IF(P21="Y",Rubric!$I$6,0),IF(O21="Y",IF(AE21>=3,Rubric!$I$7,Rubric!$I$8),0),IF(Q21="Y",Rubric!$I$9,0))) -> 5 | AC21: {=MAX(1,INDEX(Rubric!$B$5:$B$9,MATCH(T21,Rubric!$A$5:$A$9,0))-IF(AND(U21="Y",T21<>"P"),Rubric!$I$11,0))} -> 2 | AD21: {=INDEX(Rubric!$E$5:$E$9,MATCH(M21,Rubric!$D$5:$D$9,0))} -> 3 | AE21: 4 | AF21: 3 | AG21: 5 | AH21: =IF(S21="Enabler","",AB21+AC21+AD21+AE21+AF21) -> 17 | AI21: =IF(S21="Enabler","",AB21+AC21+AD21+AE21+AG21) -> 19 | AJ21: {=IF(AH21="","",INDEX(Rubric!$M$5:$M$8,MATCH(AH21,Rubric!$L$5:$L$8,1)))} -> High | AK21: {=IF(AI21="","",INDEX(Rubric!$M$5:$M$8,MATCH(AI21,Rubric!$L$5:$L$8,1)))} -> High | AL21: Strong pass: residual test A3.4; weak pass: bias inside the window; W4: no report authentication | AM21: several footprints | AN21: Observables | AO21: SC-6; SC-9 | AP21: EX-0012.06 Modify On-Board Values: Science/Payload Data (medium) | AQ21: T1565.002 Transmitted Data Manipulation (high) | AR21: high | AS21: Baseline: reproduces Table 5 of the paper | AT21: =COUNTIF('CVE Register'!$X$5:$X$61,"*"&A21&"*") -> 0 | AU21: — | AV21: L1 > L2 > L3 > L4 (4 of 4 layers) L1: A1.7 | L2: [A2.1], A2.2, A2.4 | L3: A3.1, A3.3, A3.4, A3.5, A3.6 | L4: A4.5, A4.6 Boundaries to first check A3.4/A3.5: 1 | to ATM A4.6: 2
A22: T2.02 | B22: L2 | C22: Spoofed or impersonated node reports | D22: A forged or impersonated relay node injects fabricated observable reports that the CPS fuses as genuine. | E22: Node impersonation on the relay or downlink | F22: A2.1 | G22: TB2 | H22: S | I22: T | J22: n/a: no time offset on an asset of the timing dependency | L22: AC5 | M22: T2 | N22: Y | P22: Y | R22: =COUNTIF(N22:Q22,"Y") -> 2 | S22: Leaf | T22: =IF(COUNTIFS(Binding!$A$5:$A$108,A22,Binding!$C$5:$C$108,"Attack")=0,"P","E"&MAXIFS(Binding!$J$5:$J$108,Binding!$A$5:$A$108,A22,Binding!$C$5:$C$108,"Attack")) -> E2 | U22: Y | V22: =IF(T22="P","",IF(COUNTIFS(Binding!$A$5:$A$108,A22,Binding!$C$5:$C$108,"Attack",Binding!$J$5:$J$108,MAXIFS(Binding!$J$5:$J$108,Binding!$A$5:$A$108,A22,Binding!$C$5:$C$108,"Attack"),Binding!$H$5:$H$108,"Yes")=0,"Yes","No")) -> No | W22: #50, #51, #14 | Y22: M04; M17 | Z22: 1 | AA22: 2 | AB22: =IF(S22="Enabler","",MAX(IF(N22="Y",Rubric!$I$5,0),IF(P22="Y",Rubric!$I$6,0),IF(O22="Y",IF(AE22>=3,Rubric!$I$7,Rubric!$I$8),0),IF(Q22="Y",Rubric!$I$9,0))) -> 5 | AC22: {=MAX(1,INDEX(Rubric!$B$5:$B$9,MATCH(T22,Rubric!$A$5:$A$9,0))-IF(AND(U22="Y",T22<>"P"),Rubric!$I$11,0))} -> 3 | AD22: {=INDEX(Rubric!$E$5:$E$9,MATCH(M22,Rubric!$D$5:$D$9,0))} -> 3 | AE22: 3 | AF22: 3 | AG22: 5 | AH22: =IF(S22="Enabler","",AB22+AC22+AD22+AE22+AF22) -> 17 | AI22: =IF(S22="Enabler","",AB22+AC22+AD22+AE22+AG22) -> 19 | AJ22: {=IF(AH22="","",INDEX(Rubric!$M$5:$M$8,MATCH(AH22,Rubric!$L$5:$L$8,1)))} -> High | AK22: {=IF(AI22="","",INDEX(Rubric!$M$5:$M$8,MATCH(AI22,Rubric!$L$5:$L$8,1)))} -> High | AL22: Strong pass: association/residual test (L3); weak pass: no check | AM22: one footprint | AN22: Observables | AO22: SC-6 | AP22: IA-0003 Crosslink via Compromised Neighbor; IA-0008.02 Rogue Spacecraft (medium) | AQ22: T1565.002 Transmitted Data Manipulation (medium) | AR22: medium | AS22: Validated: LLM panel and co-author evaluation | AT22: =COUNTIF('CVE Register'!$X$5:$X$61,"*"&A22&"*") -> 0 | AU22: — | AV22: L1 > L2 > L3 > L4 (4 of 4 layers) L1: A1.7 | L2: [A2.1], A2.2, A2.4 | L3: A3.1, A3.3, A3.4, A3.5, A3.6 | L4: A4.5, A4.6 Boundaries to first check A3.4/A3.5: 1 | to ATM A4.6: 2
A23: T2.03 | B23: L2 | C23: Delayed or modified reports | D23: Reports are held back, reordered or delayed selectively, distorting the time-difference solution while each message remains valid. | E23: Selective delay or modification on the relay path | F23: A2.1 | G23: TB2 | H23: T | I23: D | J23: n/a: no time offset on an asset of the timing dependency | K23: Derived | L23: AC5 | M23: T2 | N23: Y | O23: Y | R23: =COUNTIF(N23:Q23,"Y") -> 2 | S23: Leaf | T23: =IF(COUNTIFS(Binding!$A$5:$A$108,A23,Binding!$C$5:$C$108,"Attack")=0,"P","E"&MAXIFS(Binding!$J$5:$J$108,Binding!$A$5:$A$108,A23,Binding!$C$5:$C$108,"Attack")) -> E1 | U23: Y | V23: =IF(T23="P","",IF(COUNTIFS(Binding!$A$5:$A$108,A23,Binding!$C$5:$C$108,"Attack",Binding!$J$5:$J$108,MAXIFS(Binding!$J$5:$J$108,Binding!$A$5:$A$108,A23,Binding!$C$5:$C$108,"Attack"),Binding!$H$5:$H$108,"Yes")=0,"Yes","No")) -> No | W23: #51, #40 | Y23: M02; M03; M04; M17; M23 | Z23: 1 | AA23: 2 | AB23: =IF(S23="Enabler","",MAX(IF(N23="Y",Rubric!$I$5,0),IF(P23="Y",Rubric!$I$6,0),IF(O23="Y",IF(AE23>=3,Rubric!$I$7,Rubric!$I$8),0),IF(Q23="Y",Rubric!$I$9,0))) -> 5 | AC23: {=MAX(1,INDEX(Rubric!$B$5:$B$9,MATCH(T23,Rubric!$A$5:$A$9,0))-IF(AND(U23="Y",T23<>"P"),Rubric!$I$11,0))} -> 2 | AD23: {=INDEX(Rubric!$E$5:$E$9,MATCH(M23,Rubric!$D$5:$D$9,0))} -> 3 | AE23: 3 | AF23: 3 | AG23: 5 | AH23: =IF(S23="Enabler","",AB23+AC23+AD23+AE23+AF23) -> 16 | AI23: =IF(S23="Enabler","",AB23+AC23+AD23+AE23+AG23) -> 18 | AJ23: {=IF(AH23="","",INDEX(Rubric!$M$5:$M$8,MATCH(AH23,Rubric!$L$5:$L$8,1)))} -> High | AK23: {=IF(AI23="","",INDEX(Rubric!$M$5:$M$8,MATCH(AI23,Rubric!$L$5:$L$8,1)))} -> High | AL23: Strong pass: residual test (L3); weak pass: bias inside the window | AM23: one footprint | AN23: Observables | AO23: SC-9 | AP23: EX-0012.06 Modify On-Board Values: Science/Payload Data (medium) | AQ23: T1565.002 Transmitted Data Manipulation (high) | AR23: medium | AS23: Validated: LLM panel and co-author evaluation | AT23: =COUNTIF('CVE Register'!$X$5:$X$61,"*"&A23&"*") -> 0 | AU23: — | AV23: L1 > L2 > L3 > L4 (4 of 4 layers) L1: A1.7 | L2: [A2.1], A2.2, A2.4 | L3: A3.1, A3.3, A3.4, A3.5, A3.6 | L4: A4.5, A4.6 Boundaries to first check A3.4/A3.5: 1 | to ATM A4.6: 2
A24: T2.04 | B24: L2 | C24: Geometry-targeted dropping of reports | D24: Selective loss of reports from the best-placed satellites raises HDOP and magnifies any other error without a visible outage. Specific to multilateration. An enabler: it opens the stealth window. | E24: Congestion or selective packet dropping on chosen links | F24: A2.2 | G24: (none: inside a layer) | H24: D | I24: T | J24: n/a: no time offset on an asset of the timing dependency | L24: AC5 | M24: T3 | N24: Y | O24: Y | R24: =COUNTIF(N24:Q24,"Y") -> 2 | S24: Enabler | T24: =IF(COUNTIFS(Binding!$A$5:$A$108,A24,Binding!$C$5:$C$108,"Attack")=0,"P","E"&MAXIFS(Binding!$J$5:$J$108,Binding!$A$5:$A$108,A24,Binding!$C$5:$C$108,"Attack")) -> E1 | U24: Y | V24: =IF(T24="P","",IF(COUNTIFS(Binding!$A$5:$A$108,A24,Binding!$C$5:$C$108,"Attack",Binding!$J$5:$J$108,MAXIFS(Binding!$J$5:$J$108,Binding!$A$5:$A$108,A24,Binding!$C$5:$C$108,"Attack"),Binding!$H$5:$H$108,"Yes")=0,"Yes","No")) -> No | W24: #13, #16, #21 | Y24: M09; M25 | Z24: 1 | AA24: 2 | AB24: =IF(S24="Enabler","",MAX(IF(N24="Y",Rubric!$I$5,0),IF(P24="Y",Rubric!$I$6,0),IF(O24="Y",IF(AE24>=3,Rubric!$I$7,Rubric!$I$8),0),IF(Q24="Y",Rubric!$I$9,0))) | AC24: {=MAX(1,INDEX(Rubric!$B$5:$B$9,MATCH(T24,Rubric!$A$5:$A$9,0))-IF(AND(U24="Y",T24<>"P"),Rubric!$I$11,0))} -> 2 | AD24: {=INDEX(Rubric!$E$5:$E$9,MATCH(M24,Rubric!$D$5:$D$9,0))} -> 2 | AE24: 3 | AF24: 4 | AG24: 4 | AH24: =IF(S24="Enabler","",AB24+AC24+AD24+AE24+AF24) | AI24: =IF(S24="Enabler","",AB24+AC24+AD24+AE24+AG24) | AJ24: {=IF(AH24="","",INDEX(Rubric!$M$5:$M$8,MATCH(AH24,Rubric!$L$5:$L$8,1)))} | AK24: {=IF(AI24="","",INDEX(Rubric!$M$5:$M$8,MATCH(AI24,Rubric!$L$5:$L$8,1)))} | AL24: L4 only: no outage is visible, the degradation is gradual | AM24: one footprint | AN24: Geometry | AO24: SC-7 | AP24: IMP-0004 Degradation; EX-0013 Flooding (medium) | AQ24: T1499 Endpoint Denial of Service (medium) | AR24: medium | AS24: Baseline: reproduces Table 5 of the paper | AT24: =COUNTIF('CVE Register'!$X$5:$X$61,"*"&A24&"*") -> 0 | AU24: — | AV24: L1 > L2 > L3 > L4 (4 of 4 layers) L1: A1.7 | L2: [A2.2], A2.4 | L3: A3.1, A3.3, A3.4, A3.5, A3.6 | L4: A4.5, A4.6 Boundaries to first check A3.4/A3.5: 1 | to ATM A4.6: 2 Enabler: weakens a safeguard; listed assets are exposed once the enabled attack runs.
A25: T2.05 | B25: L2 | C25: Inter-satellite-link denial | D25: Disruption of ISL terminals or crosslinks cuts relay paths so that fewer reports reach the ground. No published mechanism against the crosslink terminals of an MLAT constellation. | E25: Link disruption at ISL terminals | F25: A2.2 | G25: (none: inside a layer) | H25: D | J25: n/a: no time offset on an asset of the timing dependency | L25: AC5 | M25: T3 | O25: Y | R25: =COUNTIF(N25:Q25,"Y") -> 1 | S25: Leaf | T25: =IF(COUNTIFS(Binding!$A$5:$A$108,A25,Binding!$C$5:$C$108,"Attack")=0,"P","E"&MAXIFS(Binding!$J$5:$J$108,Binding!$A$5:$A$108,A25,Binding!$C$5:$C$108,"Attack")) -> P | V25: =IF(T25="P","",IF(COUNTIFS(Binding!$A$5:$A$108,A25,Binding!$C$5:$C$108,"Attack",Binding!$J$5:$J$108,MAXIFS(Binding!$J$5:$J$108,Binding!$A$5:$A$108,A25,Binding!$C$5:$C$108,"Attack"),Binding!$H$5:$H$108,"Yes")=0,"Yes","No")) | W25: (none: postulated) | Z25: 1 | AA25: 2 | AB25: =IF(S25="Enabler","",MAX(IF(N25="Y",Rubric!$I$5,0),IF(P25="Y",Rubric!$I$6,0),IF(O25="Y",IF(AE25>=3,Rubric!$I$7,Rubric!$I$8),0),IF(Q25="Y",Rubric!$I$9,0))) -> 3 | AC25: {=MAX(1,INDEX(Rubric!$B$5:$B$9,MATCH(T25,Rubric!$A$5:$A$9,0))-IF(AND(U25="Y",T25<>"P"),Rubric!$I$11,0))} -> 1 | AD25: {=INDEX(Rubric!$E$5:$E$9,MATCH(M25,Rubric!$D$5:$D$9,0))} -> 2 | AE25: 4 | AF25: 2 | AG25: 2 | AH25: =IF(S25="Enabler","",AB25+AC25+AD25+AE25+AF25) -> 12 | AI25: =IF(S25="Enabler","",AB25+AC25+AD25+AE25+AG25) -> 12 | AJ25: {=IF(AH25="","",INDEX(Rubric!$M$5:$M$8,MATCH(AH25,Rubric!$L$5:$L$8,1)))} -> Medium | AK25: {=IF(AI25="","",INDEX(Rubric!$M$5:$M$8,MATCH(AI25,Rubric!$L$5:$L$8,1)))} -> Medium | AL25: L2: relay failure is visible as route loss | AM25: several footprints | AO25: SC-7 | AP25: IMP-0003 Denial; EX-0016 Jamming (medium) | AQ25: T0814 Denial of Service (medium) | AR25: medium | AS25: Validated: LLM panel and co-author evaluation | AT25: =COUNTIF('CVE Register'!$X$5:$X$61,"*"&A25&"*") -> 0 | AU25: — | AV25: L1 > L2 > L3 > L4 (4 of 4 layers) L1: A1.7 | L2: [A2.2], A2.4 | L3: A3.1, A3.3, A3.4, A3.5, A3.6 | L4: A4.5, A4.6 Boundaries to first check A3.4/A3.5: 1 | to ATM A4.6: 2
A26: T2.06 | B26: L2 | C26: Asymmetric delay of PTP exchanges | D26: Delaying PTP messages in one direction shifts the computed clock offset although every message stays authentic. The defining tau case: it forges neither a message nor an identity yet violates the integrity of time. | E26: One-way delay of PTP messages on the ISL | F26: A2.3 | G26: TB1 | H26: tau | I26: T | J26: Authentication-invariance test: with every message authenticated (A3) the one-way delay still shifts the offset, so primary tau. | K26: Target | L26: AC5 | M26: T3 | N26: Y | R26: =COUNTIF(N26:Q26,"Y") -> 1 | S26: Leaf | T26: =IF(COUNTIFS(Binding!$A$5:$A$108,A26,Binding!$C$5:$C$108,"Attack")=0,"P","E"&MAXIFS(Binding!$J$5:$J$108,Binding!$A$5:$A$108,A26,Binding!$C$5:$C$108,"Attack")) -> E2 | U26: Y | V26: =IF(T26="P","",IF(COUNTIFS(Binding!$A$5:$A$108,A26,Binding!$C$5:$C$108,"Attack",Binding!$J$5:$J$108,MAXIFS(Binding!$J$5:$J$108,Binding!$A$5:$A$108,A26,Binding!$C$5:$C$108,"Attack"),Binding!$H$5:$H$108,"Yes")=0,"Yes","No")) -> No | W26: #48, #40, #49 | Y26: M02; M03; M23; M24 | Z26: 3 | AA26: 4 | AB26: =IF(S26="Enabler","",MAX(IF(N26="Y",Rubric!$I$5,0),IF(P26="Y",Rubric!$I$6,0),IF(O26="Y",IF(AE26>=3,Rubric!$I$7,Rubric!$I$8),0),IF(Q26="Y",Rubric!$I$9,0))) -> 5 | AC26: {=MAX(1,INDEX(Rubric!$B$5:$B$9,MATCH(T26,Rubric!$A$5:$A$9,0))-IF(AND(U26="Y",T26<>"P"),Rubric!$I$11,0))} -> 3 | AD26: {=INDEX(Rubric!$E$5:$E$9,MATCH(M26,Rubric!$D$5:$D$9,0))} -> 2 | AE26: 3 | AF26: 3 | AG26: 5 | AH26: =IF(S26="Enabler","",AB26+AC26+AD26+AE26+AF26) -> 16 | AI26: =IF(S26="Enabler","",AB26+AC26+AD26+AE26+AG26) -> 18 | AJ26: {=IF(AH26="","",INDEX(Rubric!$M$5:$M$8,MATCH(AH26,Rubric!$L$5:$L$8,1)))} -> High | AK26: {=IF(AI26="","",INDEX(Rubric!$M$5:$M$8,MATCH(AI26,Rubric!$L$5:$L$8,1)))} -> High | AL26: Strong pass: residual test (L3); weak pass: bias inside the window | AM26: one footprint | AN26: Clock | AO26: SC-3 | AP26: EX-0014.01 Spoofing: Time Spoof; EX-0012.12 Modify On-Board Values: System Clock (medium) | AQ26: T0830 Adversary-in-the-Middle (medium) | AR26: medium | AS26: Baseline: reproduces Table 5 of the paper | AT26: =COUNTIF('CVE Register'!$X$5:$X$61,"*"&A26&"*") -> 7 | AU26: 7 CVEs: ntpd (5), ptp4l (2) | AV26: L1 > L2 > L3 > L4 (4 of 4 layers) L1: A1.4, A1.5, A1.7 | L2: [A2.3], A2.1, A2.2, A2.4 | L3: A3.1, A3.2, A3.3, A3.4, A3.5, A3.6 | L4: A4.5, A4.6 Boundaries to first check A3.4/A3.5: 3 | to ATM A4.6: 4
A27: T2.07 | B27: L2 | C27: Forged PTP messages | D27: Fabricated or replayed PTP messages set an onboard clock to a wrong offset. Defeated by authenticating the exchange, so Spoofing is primary and tau secondary. | E27: Injection or replay of time-transfer messages | F27: A2.3 | G27: TB1 | H27: S | I27: tau | J27: Authentication-invariance test: with authenticated messages the forgery fails, so the primary category is Spoofing; the time offset is a secondary tau effect. | K27: Target | L27: AC5 | M27: T3 | N27: Y | R27: =COUNTIF(N27:Q27,"Y") -> 1 | S27: Leaf | T27: =IF(COUNTIFS(Binding!$A$5:$A$108,A27,Binding!$C$5:$C$108,"Attack")=0,"P","E"&MAXIFS(Binding!$J$5:$J$108,Binding!$A$5:$A$108,A27,Binding!$C$5:$C$108,"Attack")) -> E2 | U27: Y | V27: =IF(T27="P","",IF(COUNTIFS(Binding!$A$5:$A$108,A27,Binding!$C$5:$C$108,"Attack",Binding!$J$5:$J$108,MAXIFS(Binding!$J$5:$J$108,Binding!$A$5:$A$108,A27,Binding!$C$5:$C$108,"Attack"),Binding!$H$5:$H$108,"Yes")=0,"Yes","No")) -> No | W27: #48, #49 | Y27: M02; M03; M23; M24 | Z27: 3 | AA27: 4 | AB27: =IF(S27="Enabler","",MAX(IF(N27="Y",Rubric!$I$5,0),IF(P27="Y",Rubric!$I$6,0),IF(O27="Y",IF(AE27>=3,Rubric!$I$7,Rubric!$I$8),0),IF(Q27="Y",Rubric!$I$9,0))) -> 5 | AC27: {=MAX(1,INDEX(Rubric!$B$5:$B$9,MATCH(T27,Rubric!$A$5:$A$9,0))-IF(AND(U27="Y",T27<>"P"),Rubric!$I$11,0))} -> 3 | AD27: {=INDEX(Rubric!$E$5:$E$9,MATCH(M27,Rubric!$D$5:$D$9,0))} -> 2 | AE27: 3 | AF27: 3 | AG27: 5 | AH27: =IF(S27="Enabler","",AB27+AC27+AD27+AE27+AF27) -> 16 | AI27: =IF(S27="Enabler","",AB27+AC27+AD27+AE27+AG27) -> 18 | AJ27: {=IF(AH27="","",INDEX(Rubric!$M$5:$M$8,MATCH(AH27,Rubric!$L$5:$L$8,1)))} -> High | AK27: {=IF(AI27="","",INDEX(Rubric!$M$5:$M$8,MATCH(AI27,Rubric!$L$5:$L$8,1)))} -> High | AL27: Strong pass: residual test (L3); weak pass: bias inside the window | AM27: one footprint | AN27: Clock | AO27: SC-3 | AP27: EX-0014.01 Spoofing: Time Spoof (high) | AQ27: (unmapped) | AR27: medium | AS27: Validated: LLM panel and co-author evaluation | AT27: =COUNTIF('CVE Register'!$X$5:$X$61,"*"&A27&"*") -> 7 | AU27: 7 CVEs: ntpd (5), ptp4l (2) | AV27: L1 > L2 > L3 > L4 (4 of 4 layers) L1: A1.4, A1.5, A1.7 | L2: [A2.3], A2.1, A2.2, A2.4 | L3: A3.1, A3.2, A3.3, A3.4, A3.5, A3.6 | L4: A4.5, A4.6 Boundaries to first check A3.4/A3.5: 3 | to ATM A4.6: 4
A28: T2.08 | B28: L2 | C28: Backhaul and downlink interception | D28: Passive reception of downlink or backhaul traffic discloses tracks, identities and system behaviour; disclosure is the precondition of injection (T2.09). | E28: Consumer-grade receiving equipment on the downlink | F28: A2.4 | G28: TB2 | H28: I | J28: n/a: no time offset on an asset of the timing dependency | L28: AC5 | M28: T2 | Q28: Y | R28: =COUNTIF(N28:Q28,"Y") -> 1 | S28: Leaf | T28: =IF(COUNTIFS(Binding!$A$5:$A$108,A28,Binding!$C$5:$C$108,"Attack")=0,"P","E"&MAXIFS(Binding!$J$5:$J$108,Binding!$A$5:$A$108,A28,Binding!$C$5:$C$108,"Attack")) -> E3 | U28: Y | V28: =IF(T28="P","",IF(COUNTIFS(Binding!$A$5:$A$108,A28,Binding!$C$5:$C$108,"Attack",Binding!$J$5:$J$108,MAXIFS(Binding!$J$5:$J$108,Binding!$A$5:$A$108,A28,Binding!$C$5:$C$108,"Attack"),Binding!$H$5:$H$108,"Yes")=0,"Yes","No")) -> No | W28: #2, #63, #66 | Y28: M09; M13 | Z28: 1 | AA28: 2 | AB28: =IF(S28="Enabler","",MAX(IF(N28="Y",Rubric!$I$5,0),IF(P28="Y",Rubric!$I$6,0),IF(O28="Y",IF(AE28>=3,Rubric!$I$7,Rubric!$I$8),0),IF(Q28="Y",Rubric!$I$9,0))) -> 1 | AC28: {=MAX(1,INDEX(Rubric!$B$5:$B$9,MATCH(T28,Rubric!$A$5:$A$9,0))-IF(AND(U28="Y",T28<>"P"),Rubric!$I$11,0))} -> 4 | AD28: {=INDEX(Rubric!$E$5:$E$9,MATCH(M28,Rubric!$D$5:$D$9,0))} -> 3 | AE28: 4 | AF28: 5 | AG28: 5 | AH28: =IF(S28="Enabler","",AB28+AC28+AD28+AE28+AF28) -> 17 | AI28: =IF(S28="Enabler","",AB28+AC28+AD28+AE28+AG28) -> 17 | AJ28: {=IF(AH28="","",INDEX(Rubric!$M$5:$M$8,MATCH(AH28,Rubric!$L$5:$L$8,1)))} -> High | AK28: {=IF(AI28="","",INDEX(Rubric!$M$5:$M$8,MATCH(AI28,Rubric!$L$5:$L$8,1)))} -> High | AL28: None: passive reception leaves no trace | AM28: several footprints | AO28: SC-8 | AP28: EXF-0003.02 Eavesdropping: Downlink Intercept; REC-0005.02 (high) | AQ28: T1040 Network Sniffing (medium) | AR28: high | AS28: Validated: LLM panel and co-author evaluation | AT28: =COUNTIF('CVE Register'!$X$5:$X$61,"*"&A28&"*") -> 0 | AU28: — | AV28: Contained: disclosure only, no downstream state change. Exposure at L2: [A2.4]
